2025-05-02 17:38:15,201 [INFO] Embedding generator initialized successfully
2025-05-02 17:38:15,266 [INFO] Embedding generator initialized successfully
2025-05-02 17:39:33,980 [INFO] Embedding generator initialized successfully
2025-05-02 17:39:34,037 [INFO] Embedding generator initialized successfully
2025-05-02 17:40:41,142 [ERROR] Error processing LinkedIn profile: app.db.mongodb.models.linkedin.LinkedInProfile() argument after ** must be a mapping, not TypeError
2025-05-02 17:40:41,142 [ERROR] Error processing resume: Profile processing failed: app.db.mongodb.models.linkedin.LinkedInProfile() argument after ** must be a mapping, not TypeError
Traceback (most recent call last):
  File "/home/dmnsangeeth/Desktop/project/ai-recruitment-platform/app/services/linkedin_service.py", line 57, in scraping_linkedin_content
    profile = LinkedInProfile(
        **raw_data,
        profile_url=str(linkedin_url)
    )
TypeError: app.db.mongodb.models.linkedin.LinkedInProfile() argument after ** must be a mapping, not TypeError

During handling of the above exception, another exception occurred:

Traceback (most recent call last):
  File "/home/dmnsangeeth/Desktop/project/ai-recruitment-platform/app/api/v1/endpoints/linkedin.py", line 24, in upload_linkedin_profile
    profile_data = await linkedin_service.scraping_linkedin_content(
                   ^^^^^^^^^^^^^^^^^^^^^^^^^^^^^^^^^^^^^^^^^^^^^^^^^
        linkedin_url=str(linkedin_url)
        ^^^^^^^^^^^^^^^^^^^^^^^^^^^^^^
    )
    ^
  File "/home/dmnsangeeth/Desktop/project/ai-recruitment-platform/app/services/linkedin_service.py", line 68, in scraping_linkedin_content
    raise ProfileProcessingError(f"Profile processing failed: {str(e)}")
app.utils.exceptions.ProfileProcessingError: Profile processing failed: app.db.mongodb.models.linkedin.LinkedInProfile() argument after ** must be a mapping, not TypeError
2025-05-02 17:43:56,959 [INFO] File saved at: storage/resumes/resume_20250502_174356.png
2025-05-02 17:43:58,571 [INFO] HTTP Request: POST https://generativelanguage.googleapis.com/upload/v1beta/files "HTTP/1.1 200 OK"
2025-05-02 17:44:04,830 [INFO] HTTP Request: POST https://generativelanguage.googleapis.com/upload/v1beta/files?upload_id=AAO2VwrO60ZXSubeNqZ7KekangNRTyLKqls0Y9JOLRckhq9yKww1eRObOPYorFqYN5kmdH8sOBp1igA_kMv8si7jY6QT0i4Y6yV0iOoJKr9eGA&upload_protocol=resumable "HTTP/1.1 200 OK"
2025-05-02 17:44:04,864 [INFO] AFC is enabled with max remote calls: 10.
2025-05-02 17:44:09,935 [INFO] HTTP Request: POST https://generativelanguage.googleapis.com/v1beta/models/gemini-2.0-flash:generateContent "HTTP/1.1 200 OK"
2025-05-02 17:44:09,940 [INFO] AFC remote call 1 is done.
2025-05-02 17:44:19,615 [INFO] Successfully created embedding for resume: NISHAN SANGEETH
2025-05-02 17:44:21,466 [INFO] Successfully processed and stored resume for NISHAN SANGEETH
2025-05-02 17:44:21,928 [INFO] Successfully created embedding for resume: None
2025-05-02 17:57:16,089 [INFO] Embedding generator initialized successfully
2025-05-02 17:57:16,148 [INFO] Embedding generator initialized successfully
2025-05-02 17:57:57,289 [INFO] Embedding generator initialized successfully
2025-05-02 17:57:57,342 [INFO] Embedding generator initialized successfully
2025-05-02 17:59:21,673 [ERROR] Error processing LinkedIn profile: Invalid profile data format
2025-05-02 17:59:21,673 [ERROR] Error processing LinkedIn profile: Profile processing failed: Invalid profile data format
Traceback (most recent call last):
  File "/home/dmnsangeeth/Desktop/project/ai-recruitment-platform/app/services/linkedin_service.py", line 59, in scraping_linkedin_content
    raise ProfileProcessingError("Invalid profile data format")
app.utils.exceptions.ProfileProcessingError: Invalid profile data format

During handling of the above exception, another exception occurred:

Traceback (most recent call last):
  File "/home/dmnsangeeth/Desktop/project/ai-recruitment-platform/app/api/v1/endpoints/linkedin.py", line 45, in upload_linkedin_profile
    profile_data = await linkedin_service.scraping_linkedin_content(
                   ^^^^^^^^^^^^^^^^^^^^^^^^^^^^^^^^^^^^^^^^^^^^^^^^^
        linkedin_url=str(linkedin_url))
        ^^^^^^^^^^^^^^^^^^^^^^^^^^^^^^^
  File "/home/dmnsangeeth/Desktop/project/ai-recruitment-platform/app/services/linkedin_service.py", line 74, in scraping_linkedin_content
    raise ProfileProcessingError(f"Profile processing failed: {str(e)}")
app.utils.exceptions.ProfileProcessingError: Profile processing failed: Invalid profile data format
2025-05-02 18:00:18,116 [INFO] Embedding generator initialized successfully
2025-05-02 18:00:18,177 [INFO] Embedding generator initialized successfully
2025-05-02 18:00:25,755 [ERROR] Error processing LinkedIn profile: Invalid profile data format
2025-05-02 18:00:25,756 [ERROR] Error processing LinkedIn profile: Profile processing failed: Invalid profile data format
Traceback (most recent call last):
  File "/home/dmnsangeeth/Desktop/project/ai-recruitment-platform/app/services/linkedin_service.py", line 59, in scraping_linkedin_content
    raise ProfileProcessingError("Invalid profile data format")
app.utils.exceptions.ProfileProcessingError: Invalid profile data format

During handling of the above exception, another exception occurred:

Traceback (most recent call last):
  File "/home/dmnsangeeth/Desktop/project/ai-recruitment-platform/app/api/v1/endpoints/linkedin.py", line 45, in upload_linkedin_profile
    profile_data = await linkedin_service.scraping_linkedin_content(
                   ^^^^^^^^^^^^^^^^^^^^^^^^^^^^^^^^^^^^^^^^^^^^^^^^^
        linkedin_url="https://www.linkedin.com/in/dmn-sangeeth")
        ^^^^^^^^^^^^^^^^^^^^^^^^^^^^^^^^^^^^^^^^^^^^^^^^^^^^^^^^
  File "/home/dmnsangeeth/Desktop/project/ai-recruitment-platform/app/services/linkedin_service.py", line 74, in scraping_linkedin_content
    raise ProfileProcessingError(f"Profile processing failed: {str(e)}")
app.utils.exceptions.ProfileProcessingError: Profile processing failed: Invalid profile data format
2025-05-02 18:00:58,163 [INFO] Embedding generator initialized successfully
2025-05-02 18:00:58,224 [INFO] Embedding generator initialized successfully
2025-05-02 18:01:03,140 [INFO] Embedding generator initialized successfully
2025-05-02 18:01:03,205 [INFO] Embedding generator initialized successfully
2025-05-02 18:01:57,940 [INFO] Embedding generator initialized successfully
2025-05-02 18:01:57,992 [INFO] Embedding generator initialized successfully
2025-05-02 18:02:12,110 [INFO] Embedding generator initialized successfully
2025-05-02 18:02:12,191 [INFO] Embedding generator initialized successfully
2025-05-02 18:02:24,786 [ERROR] Error processing LinkedIn profile: Invalid profile data format
2025-05-02 18:02:24,787 [ERROR] Error processing LinkedIn profile: Profile processing failed: Invalid profile data format
Traceback (most recent call last):
  File "/home/dmnsangeeth/Desktop/project/ai-recruitment-platform/app/services/linkedin_service.py", line 59, in scraping_linkedin_content
    raise ProfileProcessingError("Invalid profile data format")
app.utils.exceptions.ProfileProcessingError: Invalid profile data format

During handling of the above exception, another exception occurred:

Traceback (most recent call last):
  File "/home/dmnsangeeth/Desktop/project/ai-recruitment-platform/app/api/v1/endpoints/linkedin.py", line 46, in upload_linkedin_profile
    profile_data = await linkedin_service.scraping_linkedin_content(
                   ^^^^^^^^^^^^^^^^^^^^^^^^^^^^^^^^^^^^^^^^^^^^^^^^^
        linkedin_url=str(linkedin_url))
        ^^^^^^^^^^^^^^^^^^^^^^^^^^^^^^^
  File "/home/dmnsangeeth/Desktop/project/ai-recruitment-platform/app/services/linkedin_service.py", line 74, in scraping_linkedin_content
    raise ProfileProcessingError(f"Profile processing failed: {str(e)}")
app.utils.exceptions.ProfileProcessingError: Profile processing failed: Invalid profile data format
2025-05-02 18:03:59,042 [INFO] Embedding generator initialized successfully
2025-05-02 18:03:59,111 [INFO] Embedding generator initialized successfully
2025-05-02 18:04:10,421 [ERROR] Error processing LinkedIn profile: Invalid profile data format
2025-05-02 18:04:10,422 [ERROR] Error processing LinkedIn profile: Profile processing failed: Invalid profile data format
Traceback (most recent call last):
  File "/home/dmnsangeeth/Desktop/project/ai-recruitment-platform/app/services/linkedin_service.py", line 59, in scraping_linkedin_content
    raise ProfileProcessingError("Invalid profile data format")
app.utils.exceptions.ProfileProcessingError: Invalid profile data format

During handling of the above exception, another exception occurred:

Traceback (most recent call last):
  File "/home/dmnsangeeth/Desktop/project/ai-recruitment-platform/app/api/v1/endpoints/linkedin.py", line 46, in upload_linkedin_profile
    profile_data = await linkedin_service.scraping_linkedin_content(
                   ^^^^^^^^^^^^^^^^^^^^^^^^^^^^^^^^^^^^^^^^^^^^^^^^^
        linkedin_url=str(linkedin_url))
        ^^^^^^^^^^^^^^^^^^^^^^^^^^^^^^^
  File "/home/dmnsangeeth/Desktop/project/ai-recruitment-platform/app/services/linkedin_service.py", line 74, in scraping_linkedin_content
    raise ProfileProcessingError(f"Profile processing failed: {str(e)}")
app.utils.exceptions.ProfileProcessingError: Profile processing failed: Invalid profile data format
2025-05-02 18:04:31,313 [ERROR] Error processing LinkedIn profile: Invalid profile data format
2025-05-02 18:04:31,313 [ERROR] Error processing LinkedIn profile: Profile processing failed: Invalid profile data format
Traceback (most recent call last):
  File "/home/dmnsangeeth/Desktop/project/ai-recruitment-platform/app/services/linkedin_service.py", line 59, in scraping_linkedin_content
    raise ProfileProcessingError("Invalid profile data format")
app.utils.exceptions.ProfileProcessingError: Invalid profile data format

During handling of the above exception, another exception occurred:

Traceback (most recent call last):
  File "/home/dmnsangeeth/Desktop/project/ai-recruitment-platform/app/api/v1/endpoints/linkedin.py", line 46, in upload_linkedin_profile
    profile_data = await linkedin_service.scraping_linkedin_content(
                   ^^^^^^^^^^^^^^^^^^^^^^^^^^^^^^^^^^^^^^^^^^^^^^^^^
        linkedin_url=str(linkedin_url))
        ^^^^^^^^^^^^^^^^^^^^^^^^^^^^^^^
  File "/home/dmnsangeeth/Desktop/project/ai-recruitment-platform/app/services/linkedin_service.py", line 74, in scraping_linkedin_content
    raise ProfileProcessingError(f"Profile processing failed: {str(e)}")
app.utils.exceptions.ProfileProcessingError: Profile processing failed: Invalid profile data format
2025-05-02 18:05:12,807 [INFO] Embedding generator initialized successfully
2025-05-02 18:05:12,863 [INFO] Embedding generator initialized successfully
2025-05-02 18:05:12,876 [ERROR] Error processing LinkedIn profile: Invalid profile data format
2025-05-02 18:05:12,876 [ERROR] Error processing LinkedIn profile: Profile processing failed: Invalid profile data format
Traceback (most recent call last):
  File "/home/dmnsangeeth/Desktop/project/ai-recruitment-platform/app/services/linkedin_service.py", line 60, in scraping_linkedin_content
    raise ProfileProcessingError("Invalid profile data format")
app.utils.exceptions.ProfileProcessingError: Invalid profile data format

During handling of the above exception, another exception occurred:

Traceback (most recent call last):
  File "/home/dmnsangeeth/Desktop/project/ai-recruitment-platform/app/api/v1/endpoints/linkedin.py", line 46, in upload_linkedin_profile
    profile_data = await linkedin_service.scraping_linkedin_content(
                   ^^^^^^^^^^^^^^^^^^^^^^^^^^^^^^^^^^^^^^^^^^^^^^^^^
        linkedin_url=str(linkedin_url))
        ^^^^^^^^^^^^^^^^^^^^^^^^^^^^^^^
  File "/home/dmnsangeeth/Desktop/project/ai-recruitment-platform/app/services/linkedin_service.py", line 75, in scraping_linkedin_content
    raise ProfileProcessingError(f"Profile processing failed: {str(e)}")
app.utils.exceptions.ProfileProcessingError: Profile processing failed: Invalid profile data format
2025-05-02 18:07:09,069 [INFO] Embedding generator initialized successfully
2025-05-02 18:07:09,154 [INFO] Embedding generator initialized successfully
2025-05-02 18:07:18,620 [ERROR] Error processing LinkedIn profile: Invalid profile data format
2025-05-02 18:07:18,620 [ERROR] Error processing LinkedIn profile: Profile processing failed: Invalid profile data format
Traceback (most recent call last):
  File "/home/dmnsangeeth/Desktop/project/ai-recruitment-platform/app/services/linkedin_service.py", line 60, in scraping_linkedin_content
    raise ProfileProcessingError("Invalid profile data format")
app.utils.exceptions.ProfileProcessingError: Invalid profile data format

During handling of the above exception, another exception occurred:

Traceback (most recent call last):
  File "/home/dmnsangeeth/Desktop/project/ai-recruitment-platform/app/api/v1/endpoints/linkedin.py", line 46, in upload_linkedin_profile
    profile_data = await linkedin_service.scraping_linkedin_content(
                   ^^^^^^^^^^^^^^^^^^^^^^^^^^^^^^^^^^^^^^^^^^^^^^^^^
        linkedin_url=str(linkedin_url))
        ^^^^^^^^^^^^^^^^^^^^^^^^^^^^^^^
  File "/home/dmnsangeeth/Desktop/project/ai-recruitment-platform/app/services/linkedin_service.py", line 75, in scraping_linkedin_content
    raise ProfileProcessingError(f"Profile processing failed: {str(e)}")
app.utils.exceptions.ProfileProcessingError: Profile processing failed: Invalid profile data format
2025-05-02 18:09:05,659 [INFO] Embedding generator initialized successfully
2025-05-02 18:09:05,714 [INFO] Embedding generator initialized successfully
2025-05-02 18:09:06,784 [ERROR] Error processing LinkedIn profile: Invalid profile data format
2025-05-02 18:09:06,784 [ERROR] Error processing LinkedIn profile: Profile processing failed: Invalid profile data format
Traceback (most recent call last):
  File "/home/dmnsangeeth/Desktop/project/ai-recruitment-platform/app/services/linkedin_service.py", line 61, in scraping_linkedin_content
    raise ProfileProcessingError("Invalid profile data format")
app.utils.exceptions.ProfileProcessingError: Invalid profile data format

During handling of the above exception, another exception occurred:

Traceback (most recent call last):
  File "/home/dmnsangeeth/Desktop/project/ai-recruitment-platform/app/api/v1/endpoints/linkedin.py", line 46, in upload_linkedin_profile
    profile_data = await linkedin_service.scraping_linkedin_content(
                   ^^^^^^^^^^^^^^^^^^^^^^^^^^^^^^^^^^^^^^^^^^^^^^^^^
        linkedin_url=str(linkedin_url))
        ^^^^^^^^^^^^^^^^^^^^^^^^^^^^^^^
  File "/home/dmnsangeeth/Desktop/project/ai-recruitment-platform/app/services/linkedin_service.py", line 76, in scraping_linkedin_content
    raise ProfileProcessingError(f"Profile processing failed: {str(e)}")
app.utils.exceptions.ProfileProcessingError: Profile processing failed: Invalid profile data format
2025-05-02 18:12:41,495 [INFO] Embedding generator initialized successfully
2025-05-02 18:12:41,568 [INFO] Embedding generator initialized successfully
2025-05-02 18:12:41,627 [ERROR] Error processing LinkedIn profile: Invalid profile data format
2025-05-02 18:12:41,627 [ERROR] Error processing LinkedIn profile: Profile processing failed: Invalid profile data format
Traceback (most recent call last):
  File "/home/dmnsangeeth/Desktop/project/ai-recruitment-platform/app/services/linkedin_service.py", line 62, in scraping_linkedin_content
    raise ProfileProcessingError("Invalid profile data format")
app.utils.exceptions.ProfileProcessingError: Invalid profile data format

During handling of the above exception, another exception occurred:

Traceback (most recent call last):
  File "/home/dmnsangeeth/Desktop/project/ai-recruitment-platform/app/api/v1/endpoints/linkedin.py", line 46, in upload_linkedin_profile
    profile_data = await linkedin_service.scraping_linkedin_content(
                   ^^^^^^^^^^^^^^^^^^^^^^^^^^^^^^^^^^^^^^^^^^^^^^^^^
        linkedin_url=str(linkedin_url))
        ^^^^^^^^^^^^^^^^^^^^^^^^^^^^^^^
  File "/home/dmnsangeeth/Desktop/project/ai-recruitment-platform/app/services/linkedin_service.py", line 77, in scraping_linkedin_content
    raise ProfileProcessingError(f"Profile processing failed: {str(e)}")
app.utils.exceptions.ProfileProcessingError: Profile processing failed: Invalid profile data format
2025-05-02 18:16:06,055 [INFO] Embedding generator initialized successfully
2025-05-02 18:16:06,112 [INFO] Embedding generator initialized successfully
2025-05-02 18:16:10,244 [ERROR] Error processing LinkedIn profile: Invalid profile data format
2025-05-02 18:16:10,245 [ERROR] Error processing LinkedIn profile: Profile processing failed: Invalid profile data format
Traceback (most recent call last):
  File "/home/dmnsangeeth/Desktop/project/ai-recruitment-platform/app/services/linkedin_service.py", line 62, in scraping_linkedin_content
    raise ProfileProcessingError("Invalid profile data format")
app.utils.exceptions.ProfileProcessingError: Invalid profile data format

During handling of the above exception, another exception occurred:

Traceback (most recent call last):
  File "/home/dmnsangeeth/Desktop/project/ai-recruitment-platform/app/api/v1/endpoints/linkedin.py", line 46, in upload_linkedin_profile
    profile_data = await linkedin_service.scraping_linkedin_content(
                   ^^^^^^^^^^^^^^^^^^^^^^^^^^^^^^^^^^^^^^^^^^^^^^^^^
        linkedin_url=str(linkedin_url))
        ^^^^^^^^^^^^^^^^^^^^^^^^^^^^^^^
  File "/home/dmnsangeeth/Desktop/project/ai-recruitment-platform/app/services/linkedin_service.py", line 77, in scraping_linkedin_content
    raise ProfileProcessingError(f"Profile processing failed: {str(e)}")
app.utils.exceptions.ProfileProcessingError: Profile processing failed: Invalid profile data format
2025-05-02 18:16:24,543 [INFO] Embedding generator initialized successfully
2025-05-02 18:16:24,595 [INFO] Embedding generator initialized successfully
2025-05-02 18:18:31,867 [INFO] Embedding generator initialized successfully
2025-05-02 18:18:31,925 [INFO] Embedding generator initialized successfully
2025-05-02 18:19:18,626 [INFO] Embedding generator initialized successfully
2025-05-02 18:19:18,692 [INFO] Embedding generator initialized successfully
2025-05-02 18:19:37,231 [INFO] Embedding generator initialized successfully
2025-05-02 18:19:37,289 [INFO] Embedding generator initialized successfully
2025-05-02 18:19:49,787 [ERROR] Unexpected error: Object of type PyObjectId is not JSON serializable
2025-05-02 18:19:49,788 [ERROR] Error processing LinkedIn profile: 1 validation error for LinkedInProfile
full_name
  Field required [type=missing, input_value={'error': 'Unexpected err...in.com/in/dmn-sangeeth'}, input_type=dict]
    For further information visit https://errors.pydantic.dev/2.9/v/missing
2025-05-02 18:19:49,788 [ERROR] Error processing LinkedIn profile: Profile processing failed: 1 validation error for LinkedInProfile
full_name
  Field required [type=missing, input_value={'error': 'Unexpected err...in.com/in/dmn-sangeeth'}, input_type=dict]
    For further information visit https://errors.pydantic.dev/2.9/v/missing
Traceback (most recent call last):
  File "/home/dmnsangeeth/Desktop/project/ai-recruitment-platform/app/services/linkedin_service.py", line 89, in scraping_linkedin_content
    profile = LinkedInProfile(**profile_data)
  File "/home/dmnsangeeth/anaconda3/envs/gemini/lib/python3.13/site-packages/pydantic/main.py", line 212, in __init__
    validated_self = self.__pydantic_validator__.validate_python(data, self_instance=self)
pydantic_core._pydantic_core.ValidationError: 1 validation error for LinkedInProfile
full_name
  Field required [type=missing, input_value={'error': 'Unexpected err...in.com/in/dmn-sangeeth'}, input_type=dict]
    For further information visit https://errors.pydantic.dev/2.9/v/missing

During handling of the above exception, another exception occurred:

Traceback (most recent call last):
  File "/home/dmnsangeeth/Desktop/project/ai-recruitment-platform/app/api/v1/endpoints/linkedin.py", line 46, in upload_linkedin_profile
    profile_data = await linkedin_service.scraping_linkedin_content(
                   ^^^^^^^^^^^^^^^^^^^^^^^^^^^^^^^^^^^^^^^^^^^^^^^^^
        linkedin_url=str(linkedin_url))
        ^^^^^^^^^^^^^^^^^^^^^^^^^^^^^^^
  File "/home/dmnsangeeth/Desktop/project/ai-recruitment-platform/app/services/linkedin_service.py", line 98, in scraping_linkedin_content
    raise ProfileProcessingError(f"Profile processing failed: {str(e)}")
app.utils.exceptions.ProfileProcessingError: Profile processing failed: 1 validation error for LinkedInProfile
full_name
  Field required [type=missing, input_value={'error': 'Unexpected err...in.com/in/dmn-sangeeth'}, input_type=dict]
    For further information visit https://errors.pydantic.dev/2.9/v/missing
2025-05-02 18:20:18,388 [ERROR] Unexpected error: Object of type PyObjectId is not JSON serializable
2025-05-02 18:20:18,388 [ERROR] Error processing LinkedIn profile: 1 validation error for LinkedInProfile
full_name
  Field required [type=missing, input_value={'error': 'Unexpected err...n.com/in/dmn-sangeeth/'}, input_type=dict]
    For further information visit https://errors.pydantic.dev/2.9/v/missing
2025-05-02 18:20:18,388 [ERROR] Error processing LinkedIn profile: Profile processing failed: 1 validation error for LinkedInProfile
full_name
  Field required [type=missing, input_value={'error': 'Unexpected err...n.com/in/dmn-sangeeth/'}, input_type=dict]
    For further information visit https://errors.pydantic.dev/2.9/v/missing
Traceback (most recent call last):
  File "/home/dmnsangeeth/Desktop/project/ai-recruitment-platform/app/services/linkedin_service.py", line 89, in scraping_linkedin_content
    profile = LinkedInProfile(**profile_data)
  File "/home/dmnsangeeth/anaconda3/envs/gemini/lib/python3.13/site-packages/pydantic/main.py", line 212, in __init__
    validated_self = self.__pydantic_validator__.validate_python(data, self_instance=self)
pydantic_core._pydantic_core.ValidationError: 1 validation error for LinkedInProfile
full_name
  Field required [type=missing, input_value={'error': 'Unexpected err...n.com/in/dmn-sangeeth/'}, input_type=dict]
    For further information visit https://errors.pydantic.dev/2.9/v/missing

During handling of the above exception, another exception occurred:

Traceback (most recent call last):
  File "/home/dmnsangeeth/Desktop/project/ai-recruitment-platform/app/api/v1/endpoints/linkedin.py", line 46, in upload_linkedin_profile
    profile_data = await linkedin_service.scraping_linkedin_content(
                   ^^^^^^^^^^^^^^^^^^^^^^^^^^^^^^^^^^^^^^^^^^^^^^^^^
        linkedin_url=str(linkedin_url))
        ^^^^^^^^^^^^^^^^^^^^^^^^^^^^^^^
  File "/home/dmnsangeeth/Desktop/project/ai-recruitment-platform/app/services/linkedin_service.py", line 98, in scraping_linkedin_content
    raise ProfileProcessingError(f"Profile processing failed: {str(e)}")
app.utils.exceptions.ProfileProcessingError: Profile processing failed: 1 validation error for LinkedInProfile
full_name
  Field required [type=missing, input_value={'error': 'Unexpected err...n.com/in/dmn-sangeeth/'}, input_type=dict]
    For further information visit https://errors.pydantic.dev/2.9/v/missing
2025-05-02 18:22:30,126 [INFO] Embedding generator initialized successfully
2025-05-02 18:22:30,192 [INFO] Embedding generator initialized successfully
2025-05-02 18:22:30,206 [ERROR] Error processing LinkedIn profile: 'pydantic_core._pydantic_core.Url' object has no attribute 'startswith'
2025-05-02 18:22:30,206 [ERROR] Error processing LinkedIn profile: Profile processing failed: 'pydantic_core._pydantic_core.Url' object has no attribute 'startswith'
Traceback (most recent call last):
  File "/home/dmnsangeeth/Desktop/project/ai-recruitment-platform/app/services/linkedin_service.py", line 77, in scraping_linkedin_content
    raw_data = await self.fetch_raw_profile(linkedin_url)
               ^^^^^^^^^^^^^^^^^^^^^^^^^^^^^^^^^^^^^^^^^^
  File "/home/dmnsangeeth/Desktop/project/ai-recruitment-platform/app/services/linkedin_service.py", line 26, in fetch_raw_profile
    validate_url = self.validator.validate_linkedin_url(linkedin_url)
  File "/home/dmnsangeeth/Desktop/project/ai-recruitment-platform/app/core/validation/linkedin_validator.py", line 15, in validate_linkedin_url
    return any(url.startswith(prefix) for prefix in valid_prefixes)
  File "/home/dmnsangeeth/Desktop/project/ai-recruitment-platform/app/core/validation/linkedin_validator.py", line 15, in <genexpr>
    return any(url.startswith(prefix) for prefix in valid_prefixes)
               ^^^^^^^^^^^^^^
AttributeError: 'pydantic_core._pydantic_core.Url' object has no attribute 'startswith'

During handling of the above exception, another exception occurred:

Traceback (most recent call last):
  File "/home/dmnsangeeth/Desktop/project/ai-recruitment-platform/app/api/v1/endpoints/linkedin.py", line 46, in upload_linkedin_profile
    profile_data = await linkedin_service.scraping_linkedin_content(
                   ^^^^^^^^^^^^^^^^^^^^^^^^^^^^^^^^^^^^^^^^^^^^^^^^^
        linkedin_url=linkedin_url)
        ^^^^^^^^^^^^^^^^^^^^^^^^^^
  File "/home/dmnsangeeth/Desktop/project/ai-recruitment-platform/app/services/linkedin_service.py", line 98, in scraping_linkedin_content
    raise ProfileProcessingError(f"Profile processing failed: {str(e)}")
app.utils.exceptions.ProfileProcessingError: Profile processing failed: 'pydantic_core._pydantic_core.Url' object has no attribute 'startswith'
2025-05-02 18:27:18,212 [INFO] Embedding generator initialized successfully
2025-05-02 18:27:18,269 [INFO] Embedding generator initialized successfully
2025-05-02 18:28:09,941 [INFO] Embedding generator initialized successfully
2025-05-02 18:28:09,997 [INFO] Embedding generator initialized successfully
2025-05-02 18:28:43,017 [INFO] Embedding generator initialized successfully
2025-05-02 18:28:43,076 [INFO] Embedding generator initialized successfully
2025-05-02 18:28:43,090 [ERROR] Error processing LinkedIn profile: 'pydantic_core._pydantic_core.Url' object has no attribute 'startswith'
2025-05-02 18:28:43,090 [ERROR] Error processing LinkedIn profile: Profile processing failed: 'pydantic_core._pydantic_core.Url' object has no attribute 'startswith'
Traceback (most recent call last):
  File "/home/dmnsangeeth/Desktop/project/ai-recruitment-platform/app/services/linkedin_service.py", line 85, in scraping_linkedin_content
    raw_data = await self.fetch_raw_profile(linkedin_url)
               ^^^^^^^^^^^^^^^^^^^^^^^^^^^^^^^^^^^^^^^^^^
  File "/home/dmnsangeeth/Desktop/project/ai-recruitment-platform/app/services/linkedin_service.py", line 26, in fetch_raw_profile
    validate_url = self.validator.validate_linkedin_url(linkedin_url)
  File "/home/dmnsangeeth/Desktop/project/ai-recruitment-platform/app/core/validation/linkedin_validator.py", line 15, in validate_linkedin_url
    return any(url.startswith(prefix) for prefix in valid_prefixes)
  File "/home/dmnsangeeth/Desktop/project/ai-recruitment-platform/app/core/validation/linkedin_validator.py", line 15, in <genexpr>
    return any(url.startswith(prefix) for prefix in valid_prefixes)
               ^^^^^^^^^^^^^^
AttributeError: 'pydantic_core._pydantic_core.Url' object has no attribute 'startswith'

During handling of the above exception, another exception occurred:

Traceback (most recent call last):
  File "/home/dmnsangeeth/Desktop/project/ai-recruitment-platform/app/api/v1/endpoints/linkedin.py", line 46, in upload_linkedin_profile
    profile_data = await linkedin_service.scraping_linkedin_content(
                   ^^^^^^^^^^^^^^^^^^^^^^^^^^^^^^^^^^^^^^^^^^^^^^^^^
        linkedin_url=linkedin_url)
        ^^^^^^^^^^^^^^^^^^^^^^^^^^
  File "/home/dmnsangeeth/Desktop/project/ai-recruitment-platform/app/services/linkedin_service.py", line 106, in scraping_linkedin_content
    raise ProfileProcessingError(f"Profile processing failed: {str(e)}")
app.utils.exceptions.ProfileProcessingError: Profile processing failed: 'pydantic_core._pydantic_core.Url' object has no attribute 'startswith'
2025-05-02 18:29:06,961 [INFO] Embedding generator initialized successfully
2025-05-02 18:29:07,020 [INFO] Embedding generator initialized successfully
2025-05-02 18:29:07,034 [ERROR] Unexpected error: Object of type Url is not JSON serializable
2025-05-02 18:29:07,034 [ERROR] Error processing LinkedIn profile: 1 validation error for LinkedInProfile
full_name
  Field required [type=missing, input_value={'error': 'Unexpected err...n.com/in/dmn-sangeeth/'}, input_type=dict]
    For further information visit https://errors.pydantic.dev/2.9/v/missing
2025-05-02 18:29:07,034 [ERROR] Error processing LinkedIn profile: Profile processing failed: 1 validation error for LinkedInProfile
full_name
  Field required [type=missing, input_value={'error': 'Unexpected err...n.com/in/dmn-sangeeth/'}, input_type=dict]
    For further information visit https://errors.pydantic.dev/2.9/v/missing
Traceback (most recent call last):
  File "/home/dmnsangeeth/Desktop/project/ai-recruitment-platform/app/services/linkedin_service.py", line 97, in scraping_linkedin_content
    profile = LinkedInProfile(**profile_data)
  File "/home/dmnsangeeth/anaconda3/envs/gemini/lib/python3.13/site-packages/pydantic/main.py", line 212, in __init__
    validated_self = self.__pydantic_validator__.validate_python(data, self_instance=self)
pydantic_core._pydantic_core.ValidationError: 1 validation error for LinkedInProfile
full_name
  Field required [type=missing, input_value={'error': 'Unexpected err...n.com/in/dmn-sangeeth/'}, input_type=dict]
    For further information visit https://errors.pydantic.dev/2.9/v/missing

During handling of the above exception, another exception occurred:

Traceback (most recent call last):
  File "/home/dmnsangeeth/Desktop/project/ai-recruitment-platform/app/api/v1/endpoints/linkedin.py", line 46, in upload_linkedin_profile
    profile_data = await linkedin_service.scraping_linkedin_content(
                   ^^^^^^^^^^^^^^^^^^^^^^^^^^^^^^^^^^^^^^^^^^^^^^^^^
        linkedin_url=str(linkedin_url))
        ^^^^^^^^^^^^^^^^^^^^^^^^^^^^^^^
  File "/home/dmnsangeeth/Desktop/project/ai-recruitment-platform/app/services/linkedin_service.py", line 106, in scraping_linkedin_content
    raise ProfileProcessingError(f"Profile processing failed: {str(e)}")
app.utils.exceptions.ProfileProcessingError: Profile processing failed: 1 validation error for LinkedInProfile
full_name
  Field required [type=missing, input_value={'error': 'Unexpected err...n.com/in/dmn-sangeeth/'}, input_type=dict]
    For further information visit https://errors.pydantic.dev/2.9/v/missing
2025-05-02 18:37:48,185 [INFO] Embedding generator initialized successfully
2025-05-02 18:37:48,266 [INFO] Embedding generator initialized successfully
2025-05-02 18:37:56,340 [ERROR] Unexpected error: Object of type Url is not JSON serializable
2025-05-02 18:37:56,340 [ERROR] Error processing LinkedIn profile: 1 validation error for LinkedInProfile
full_name
  Field required [type=missing, input_value={'error': 'Unexpected err...n.com/in/dmn-sangeeth/'}, input_type=dict]
    For further information visit https://errors.pydantic.dev/2.9/v/missing
2025-05-02 18:37:56,340 [ERROR] Error processing LinkedIn profile: Profile processing failed: 1 validation error for LinkedInProfile
full_name
  Field required [type=missing, input_value={'error': 'Unexpected err...n.com/in/dmn-sangeeth/'}, input_type=dict]
    For further information visit https://errors.pydantic.dev/2.9/v/missing
Traceback (most recent call last):
  File "/home/dmnsangeeth/Desktop/project/ai-recruitment-platform/app/services/linkedin_service.py", line 98, in scraping_linkedin_content
    profile = LinkedInProfile(**profile_data)
  File "/home/dmnsangeeth/anaconda3/envs/gemini/lib/python3.13/site-packages/pydantic/main.py", line 212, in __init__
    validated_self = self.__pydantic_validator__.validate_python(data, self_instance=self)
pydantic_core._pydantic_core.ValidationError: 1 validation error for LinkedInProfile
full_name
  Field required [type=missing, input_value={'error': 'Unexpected err...n.com/in/dmn-sangeeth/'}, input_type=dict]
    For further information visit https://errors.pydantic.dev/2.9/v/missing

During handling of the above exception, another exception occurred:

Traceback (most recent call last):
  File "/home/dmnsangeeth/Desktop/project/ai-recruitment-platform/app/api/v1/endpoints/linkedin.py", line 46, in upload_linkedin_profile
    profile_data = await linkedin_service.scraping_linkedin_content(
                   ^^^^^^^^^^^^^^^^^^^^^^^^^^^^^^^^^^^^^^^^^^^^^^^^^
        linkedin_url=str(linkedin_url))
        ^^^^^^^^^^^^^^^^^^^^^^^^^^^^^^^
  File "/home/dmnsangeeth/Desktop/project/ai-recruitment-platform/app/services/linkedin_service.py", line 107, in scraping_linkedin_content
    raise ProfileProcessingError(f"Profile processing failed: {str(e)}")
app.utils.exceptions.ProfileProcessingError: Profile processing failed: 1 validation error for LinkedInProfile
full_name
  Field required [type=missing, input_value={'error': 'Unexpected err...n.com/in/dmn-sangeeth/'}, input_type=dict]
    For further information visit https://errors.pydantic.dev/2.9/v/missing
2025-05-02 18:40:59,820 [INFO] Embedding generator initialized successfully
2025-05-02 18:40:59,904 [INFO] Embedding generator initialized successfully
2025-05-02 18:41:00,380 [ERROR] Unexpected error: 'dict' object has no attribute 'dict'
2025-05-02 18:41:00,380 [ERROR] Error processing LinkedIn profile: 1 validation error for LinkedInProfile
full_name
  Field required [type=missing, input_value={'error': "Unexpected err...n.com/in/dmn-sangeeth/'}, input_type=dict]
    For further information visit https://errors.pydantic.dev/2.9/v/missing
2025-05-02 18:41:00,381 [ERROR] Error processing LinkedIn profile: Profile processing failed: 1 validation error for LinkedInProfile
full_name
  Field required [type=missing, input_value={'error': "Unexpected err...n.com/in/dmn-sangeeth/'}, input_type=dict]
    For further information visit https://errors.pydantic.dev/2.9/v/missing
Traceback (most recent call last):
  File "/home/dmnsangeeth/Desktop/project/ai-recruitment-platform/app/services/linkedin_service.py", line 118, in scraping_linkedin_content
    profile = LinkedInProfile(**profile_data)
  File "/home/dmnsangeeth/anaconda3/envs/gemini/lib/python3.13/site-packages/pydantic/main.py", line 212, in __init__
    validated_self = self.__pydantic_validator__.validate_python(data, self_instance=self)
pydantic_core._pydantic_core.ValidationError: 1 validation error for LinkedInProfile
full_name
  Field required [type=missing, input_value={'error': "Unexpected err...n.com/in/dmn-sangeeth/'}, input_type=dict]
    For further information visit https://errors.pydantic.dev/2.9/v/missing

During handling of the above exception, another exception occurred:

Traceback (most recent call last):
  File "/home/dmnsangeeth/Desktop/project/ai-recruitment-platform/app/api/v1/endpoints/linkedin.py", line 46, in upload_linkedin_profile
    profile_data = await linkedin_service.scraping_linkedin_content(
                   ^^^^^^^^^^^^^^^^^^^^^^^^^^^^^^^^^^^^^^^^^^^^^^^^^
        linkedin_url=str(linkedin_url))
        ^^^^^^^^^^^^^^^^^^^^^^^^^^^^^^^
  File "/home/dmnsangeeth/Desktop/project/ai-recruitment-platform/app/services/linkedin_service.py", line 127, in scraping_linkedin_content
    raise ProfileProcessingError(f"Profile processing failed: {str(e)}")
app.utils.exceptions.ProfileProcessingError: Profile processing failed: 1 validation error for LinkedInProfile
full_name
  Field required [type=missing, input_value={'error': "Unexpected err...n.com/in/dmn-sangeeth/'}, input_type=dict]
    For further information visit https://errors.pydantic.dev/2.9/v/missing
2025-05-02 18:41:41,372 [INFO] Embedding generator initialized successfully
2025-05-02 18:41:41,453 [INFO] Embedding generator initialized successfully
2025-05-02 18:41:41,474 [ERROR] API request failed: No connection adapters were found for '8f40138a7b22-4b6d-8b9a-8474a3de12bc?project=https://api-f1db6c.stack.tryrelevance.com/latest/studios/d58d3b72-d349-44f4-b5f9-9f03f090fa7a/trigger_webhook'
2025-05-02 18:41:41,474 [ERROR] Error processing LinkedIn profile: 1 validation error for LinkedInProfile
full_name
  Field required [type=missing, input_value={'error': "API request fa...n.com/in/dmn-sangeeth/'}, input_type=dict]
    For further information visit https://errors.pydantic.dev/2.9/v/missing
2025-05-02 18:41:41,474 [ERROR] Error processing LinkedIn profile: Profile processing failed: 1 validation error for LinkedInProfile
full_name
  Field required [type=missing, input_value={'error': "API request fa...n.com/in/dmn-sangeeth/'}, input_type=dict]
    For further information visit https://errors.pydantic.dev/2.9/v/missing
Traceback (most recent call last):
  File "/home/dmnsangeeth/Desktop/project/ai-recruitment-platform/app/services/linkedin_service.py", line 118, in scraping_linkedin_content
    profile = LinkedInProfile(**profile_data)
  File "/home/dmnsangeeth/anaconda3/envs/gemini/lib/python3.13/site-packages/pydantic/main.py", line 212, in __init__
    validated_self = self.__pydantic_validator__.validate_python(data, self_instance=self)
pydantic_core._pydantic_core.ValidationError: 1 validation error for LinkedInProfile
full_name
  Field required [type=missing, input_value={'error': "API request fa...n.com/in/dmn-sangeeth/'}, input_type=dict]
    For further information visit https://errors.pydantic.dev/2.9/v/missing

During handling of the above exception, another exception occurred:

Traceback (most recent call last):
  File "/home/dmnsangeeth/Desktop/project/ai-recruitment-platform/app/api/v1/endpoints/linkedin.py", line 46, in upload_linkedin_profile
    profile_data = await linkedin_service.scraping_linkedin_content(
                   ^^^^^^^^^^^^^^^^^^^^^^^^^^^^^^^^^^^^^^^^^^^^^^^^^
        linkedin_url=str(linkedin_url))
        ^^^^^^^^^^^^^^^^^^^^^^^^^^^^^^^
  File "/home/dmnsangeeth/Desktop/project/ai-recruitment-platform/app/services/linkedin_service.py", line 127, in scraping_linkedin_content
    raise ProfileProcessingError(f"Profile processing failed: {str(e)}")
app.utils.exceptions.ProfileProcessingError: Profile processing failed: 1 validation error for LinkedInProfile
full_name
  Field required [type=missing, input_value={'error': "API request fa...n.com/in/dmn-sangeeth/'}, input_type=dict]
    For further information visit https://errors.pydantic.dev/2.9/v/missing
2025-05-02 18:43:05,252 [INFO] Embedding generator initialized successfully
2025-05-02 18:43:05,316 [INFO] Embedding generator initialized successfully
2025-05-02 18:43:23,659 [INFO] Embedding generator initialized successfully
2025-05-02 18:43:23,712 [INFO] Embedding generator initialized successfully
2025-05-02 18:43:41,786 [ERROR] API request failed: No connection adapters were found for '8f40138a7b22-4b6d-8b9a-8474a3de12bc?project=https://api-f1db6c.stack.tryrelevance.com/latest/studios/d58d3b72-d349-44f4-b5f9-9f03f090fa7a/trigger_webhook'
2025-05-02 18:43:41,786 [ERROR] Error processing LinkedIn profile: 1 validation error for LinkedInProfile
full_name
  Field required [type=missing, input_value={'error': "API request fa...in.com/in/dmn-sangeeth'}, input_type=dict]
    For further information visit https://errors.pydantic.dev/2.9/v/missing
2025-05-02 18:43:41,787 [ERROR] Error processing LinkedIn profile: Profile processing failed: 1 validation error for LinkedInProfile
full_name
  Field required [type=missing, input_value={'error': "API request fa...in.com/in/dmn-sangeeth'}, input_type=dict]
    For further information visit https://errors.pydantic.dev/2.9/v/missing
Traceback (most recent call last):
  File "/home/dmnsangeeth/Desktop/project/ai-recruitment-platform/app/services/linkedin_service.py", line 119, in scraping_linkedin_content
    profile = LinkedInProfile(**profile_data)
  File "/home/dmnsangeeth/anaconda3/envs/gemini/lib/python3.13/site-packages/pydantic/main.py", line 212, in __init__
    validated_self = self.__pydantic_validator__.validate_python(data, self_instance=self)
pydantic_core._pydantic_core.ValidationError: 1 validation error for LinkedInProfile
full_name
  Field required [type=missing, input_value={'error': "API request fa...in.com/in/dmn-sangeeth'}, input_type=dict]
    For further information visit https://errors.pydantic.dev/2.9/v/missing

During handling of the above exception, another exception occurred:

Traceback (most recent call last):
  File "/home/dmnsangeeth/Desktop/project/ai-recruitment-platform/app/api/v1/endpoints/linkedin.py", line 46, in upload_linkedin_profile
    profile_data = await linkedin_service.scraping_linkedin_content(
                   ^^^^^^^^^^^^^^^^^^^^^^^^^^^^^^^^^^^^^^^^^^^^^^^^^
        linkedin_url=str(linkedin_url))
        ^^^^^^^^^^^^^^^^^^^^^^^^^^^^^^^
  File "/home/dmnsangeeth/Desktop/project/ai-recruitment-platform/app/services/linkedin_service.py", line 128, in scraping_linkedin_content
    raise ProfileProcessingError(f"Profile processing failed: {str(e)}")
app.utils.exceptions.ProfileProcessingError: Profile processing failed: 1 validation error for LinkedInProfile
full_name
  Field required [type=missing, input_value={'error': "API request fa...in.com/in/dmn-sangeeth'}, input_type=dict]
    For further information visit https://errors.pydantic.dev/2.9/v/missing
2025-05-02 18:45:04,870 [INFO] Embedding generator initialized successfully
2025-05-02 18:45:04,953 [INFO] Embedding generator initialized successfully
2025-05-02 18:46:28,933 [INFO] Embedding generator initialized successfully
2025-05-02 18:46:28,994 [INFO] Embedding generator initialized successfully
2025-05-02 18:46:39,174 [INFO] Embedding generator initialized successfully
2025-05-02 18:46:39,240 [INFO] Embedding generator initialized successfully
2025-05-02 18:46:39,256 [ERROR] Unexpected error: Timeout value connect was 30, but it must be an int, float or None.
2025-05-02 18:46:39,257 [ERROR] Error processing LinkedIn profile: 1 validation error for LinkedInProfile
full_name
  Field required [type=missing, input_value={'error': 'Unexpected err...in.com/in/dmn-sangeeth'}, input_type=dict]
    For further information visit https://errors.pydantic.dev/2.9/v/missing
2025-05-02 18:46:39,257 [ERROR] Error processing LinkedIn profile: Profile processing failed: 1 validation error for LinkedInProfile
full_name
  Field required [type=missing, input_value={'error': 'Unexpected err...in.com/in/dmn-sangeeth'}, input_type=dict]
    For further information visit https://errors.pydantic.dev/2.9/v/missing
Traceback (most recent call last):
  File "/home/dmnsangeeth/Desktop/project/ai-recruitment-platform/app/services/linkedin_service.py", line 119, in scraping_linkedin_content
    profile = LinkedInProfile(**profile_data)
  File "/home/dmnsangeeth/anaconda3/envs/gemini/lib/python3.13/site-packages/pydantic/main.py", line 212, in __init__
    validated_self = self.__pydantic_validator__.validate_python(data, self_instance=self)
pydantic_core._pydantic_core.ValidationError: 1 validation error for LinkedInProfile
full_name
  Field required [type=missing, input_value={'error': 'Unexpected err...in.com/in/dmn-sangeeth'}, input_type=dict]
    For further information visit https://errors.pydantic.dev/2.9/v/missing

During handling of the above exception, another exception occurred:

Traceback (most recent call last):
  File "/home/dmnsangeeth/Desktop/project/ai-recruitment-platform/app/api/v1/endpoints/linkedin.py", line 46, in upload_linkedin_profile
    profile_data = await linkedin_service.scraping_linkedin_content(
                   ^^^^^^^^^^^^^^^^^^^^^^^^^^^^^^^^^^^^^^^^^^^^^^^^^
        linkedin_url=str(linkedin_url))
        ^^^^^^^^^^^^^^^^^^^^^^^^^^^^^^^
  File "/home/dmnsangeeth/Desktop/project/ai-recruitment-platform/app/services/linkedin_service.py", line 128, in scraping_linkedin_content
    raise ProfileProcessingError(f"Profile processing failed: {str(e)}")
app.utils.exceptions.ProfileProcessingError: Profile processing failed: 1 validation error for LinkedInProfile
full_name
  Field required [type=missing, input_value={'error': 'Unexpected err...in.com/in/dmn-sangeeth'}, input_type=dict]
    For further information visit https://errors.pydantic.dev/2.9/v/missing
2025-05-02 18:47:54,919 [INFO] Embedding generator initialized successfully
2025-05-02 18:47:54,981 [INFO] Embedding generator initialized successfully
2025-05-02 18:47:56,106 [ERROR] API request failed: 403 Client Error: Forbidden for url: https://api-f1db6c.stack.tryrelevance.com/latest/studios/d58d3b72-d349-44f4-b5f9-9f03f090fa7a/trigger_webhook?project=8f40138a7b22-4b6d-8b9a-8474a3de12bc
2025-05-02 18:47:56,107 [ERROR] Error processing LinkedIn profile: 1 validation error for LinkedInProfile
full_name
  Field required [type=missing, input_value={'error': 'API request fa...in.com/in/dmn-sangeeth'}, input_type=dict]
    For further information visit https://errors.pydantic.dev/2.9/v/missing
2025-05-02 18:47:56,107 [ERROR] Error processing LinkedIn profile: Profile processing failed: 1 validation error for LinkedInProfile
full_name
  Field required [type=missing, input_value={'error': 'API request fa...in.com/in/dmn-sangeeth'}, input_type=dict]
    For further information visit https://errors.pydantic.dev/2.9/v/missing
Traceback (most recent call last):
  File "/home/dmnsangeeth/Desktop/project/ai-recruitment-platform/app/services/linkedin_service.py", line 119, in scraping_linkedin_content
    profile = LinkedInProfile(**profile_data)
  File "/home/dmnsangeeth/anaconda3/envs/gemini/lib/python3.13/site-packages/pydantic/main.py", line 212, in __init__
    validated_self = self.__pydantic_validator__.validate_python(data, self_instance=self)
pydantic_core._pydantic_core.ValidationError: 1 validation error for LinkedInProfile
full_name
  Field required [type=missing, input_value={'error': 'API request fa...in.com/in/dmn-sangeeth'}, input_type=dict]
    For further information visit https://errors.pydantic.dev/2.9/v/missing

During handling of the above exception, another exception occurred:

Traceback (most recent call last):
  File "/home/dmnsangeeth/Desktop/project/ai-recruitment-platform/app/api/v1/endpoints/linkedin.py", line 46, in upload_linkedin_profile
    profile_data = await linkedin_service.scraping_linkedin_content(
                   ^^^^^^^^^^^^^^^^^^^^^^^^^^^^^^^^^^^^^^^^^^^^^^^^^
        linkedin_url=str(linkedin_url))
        ^^^^^^^^^^^^^^^^^^^^^^^^^^^^^^^
  File "/home/dmnsangeeth/Desktop/project/ai-recruitment-platform/app/services/linkedin_service.py", line 128, in scraping_linkedin_content
    raise ProfileProcessingError(f"Profile processing failed: {str(e)}")
app.utils.exceptions.ProfileProcessingError: Profile processing failed: 1 validation error for LinkedInProfile
full_name
  Field required [type=missing, input_value={'error': 'API request fa...in.com/in/dmn-sangeeth'}, input_type=dict]
    For further information visit https://errors.pydantic.dev/2.9/v/missing
2025-05-02 18:48:47,149 [ERROR] API request failed: 403 Client Error: Forbidden for url: https://api-f1db6c.stack.tryrelevance.com/latest/studios/d58d3b72-d349-44f4-b5f9-9f03f090fa7a/trigger_webhook?project=8f40138a7b22-4b6d-8b9a-8474a3de12bc
2025-05-02 18:48:47,150 [ERROR] Error processing LinkedIn profile: 1 validation error for LinkedInProfile
full_name
  Field required [type=missing, input_value={'error': 'API request fa...n.com/in/dmn-sangeeth/'}, input_type=dict]
    For further information visit https://errors.pydantic.dev/2.9/v/missing
2025-05-02 18:48:47,150 [ERROR] Error processing LinkedIn profile: Profile processing failed: 1 validation error for LinkedInProfile
full_name
  Field required [type=missing, input_value={'error': 'API request fa...n.com/in/dmn-sangeeth/'}, input_type=dict]
    For further information visit https://errors.pydantic.dev/2.9/v/missing
Traceback (most recent call last):
  File "/home/dmnsangeeth/Desktop/project/ai-recruitment-platform/app/services/linkedin_service.py", line 119, in scraping_linkedin_content
    profile = LinkedInProfile(**profile_data)
  File "/home/dmnsangeeth/anaconda3/envs/gemini/lib/python3.13/site-packages/pydantic/main.py", line 212, in __init__
    validated_self = self.__pydantic_validator__.validate_python(data, self_instance=self)
pydantic_core._pydantic_core.ValidationError: 1 validation error for LinkedInProfile
full_name
  Field required [type=missing, input_value={'error': 'API request fa...n.com/in/dmn-sangeeth/'}, input_type=dict]
    For further information visit https://errors.pydantic.dev/2.9/v/missing

During handling of the above exception, another exception occurred:

Traceback (most recent call last):
  File "/home/dmnsangeeth/Desktop/project/ai-recruitment-platform/app/api/v1/endpoints/linkedin.py", line 46, in upload_linkedin_profile
    profile_data = await linkedin_service.scraping_linkedin_content(
                   ^^^^^^^^^^^^^^^^^^^^^^^^^^^^^^^^^^^^^^^^^^^^^^^^^
        linkedin_url=str(linkedin_url))
        ^^^^^^^^^^^^^^^^^^^^^^^^^^^^^^^
  File "/home/dmnsangeeth/Desktop/project/ai-recruitment-platform/app/services/linkedin_service.py", line 128, in scraping_linkedin_content
    raise ProfileProcessingError(f"Profile processing failed: {str(e)}")
app.utils.exceptions.ProfileProcessingError: Profile processing failed: 1 validation error for LinkedInProfile
full_name
  Field required [type=missing, input_value={'error': 'API request fa...n.com/in/dmn-sangeeth/'}, input_type=dict]
    For further information visit https://errors.pydantic.dev/2.9/v/missing
2025-05-02 18:51:23,174 [INFO] Embedding generator initialized successfully
2025-05-02 18:51:23,232 [INFO] Embedding generator initialized successfully
2025-05-02 18:51:38,317 [INFO] Embedding generator initialized successfully
2025-05-02 18:51:38,407 [INFO] Embedding generator initialized successfully
2025-05-02 18:52:26,064 [INFO] Embedding generator initialized successfully
2025-05-02 18:52:26,130 [INFO] Embedding generator initialized successfully
2025-05-02 18:52:27,454 [ERROR] API request failed: 403 Client Error: Forbidden for url: https://api-f1db6c.stack.tryrelevance.com/latest/studios/d58d3b72-d349-44f4-b5f9-9f03f090fa7a/trigger_webhook?project=8f40138a7b22-4b6d-8b9a-8474a3de12bc
2025-05-02 18:52:27,454 [ERROR] Error processing LinkedIn profile: 1 validation error for LinkedInProfile
full_name
  Field required [type=missing, input_value={'error': 'API request fa...n.com/in/dmn-sangeeth/'}, input_type=dict]
    For further information visit https://errors.pydantic.dev/2.9/v/missing
2025-05-02 18:52:27,455 [ERROR] Error processing LinkedIn profile: Profile processing failed: 1 validation error for LinkedInProfile
full_name
  Field required [type=missing, input_value={'error': 'API request fa...n.com/in/dmn-sangeeth/'}, input_type=dict]
    For further information visit https://errors.pydantic.dev/2.9/v/missing
Traceback (most recent call last):
  File "/home/dmnsangeeth/Desktop/project/ai-recruitment-platform/app/services/linkedin_service.py", line 119, in scraping_linkedin_content
    profile = LinkedInProfile(**profile_data)
  File "/home/dmnsangeeth/anaconda3/envs/gemini/lib/python3.13/site-packages/pydantic/main.py", line 212, in __init__
    validated_self = self.__pydantic_validator__.validate_python(data, self_instance=self)
pydantic_core._pydantic_core.ValidationError: 1 validation error for LinkedInProfile
full_name
  Field required [type=missing, input_value={'error': 'API request fa...n.com/in/dmn-sangeeth/'}, input_type=dict]
    For further information visit https://errors.pydantic.dev/2.9/v/missing

During handling of the above exception, another exception occurred:

Traceback (most recent call last):
  File "/home/dmnsangeeth/Desktop/project/ai-recruitment-platform/app/api/v1/endpoints/linkedin.py", line 46, in upload_linkedin_profile
    profile_data = await linkedin_service.scraping_linkedin_content(
                   ^^^^^^^^^^^^^^^^^^^^^^^^^^^^^^^^^^^^^^^^^^^^^^^^^
        linkedin_url=str(linkedin_url))
        ^^^^^^^^^^^^^^^^^^^^^^^^^^^^^^^
  File "/home/dmnsangeeth/Desktop/project/ai-recruitment-platform/app/services/linkedin_service.py", line 128, in scraping_linkedin_content
    raise ProfileProcessingError(f"Profile processing failed: {str(e)}")
app.utils.exceptions.ProfileProcessingError: Profile processing failed: 1 validation error for LinkedInProfile
full_name
  Field required [type=missing, input_value={'error': 'API request fa...n.com/in/dmn-sangeeth/'}, input_type=dict]
    For further information visit https://errors.pydantic.dev/2.9/v/missing
2025-05-02 18:52:41,279 [ERROR] API request failed: 403 Client Error: Forbidden for url: https://api-f1db6c.stack.tryrelevance.com/latest/studios/d58d3b72-d349-44f4-b5f9-9f03f090fa7a/trigger_webhook?project=8f40138a7b22-4b6d-8b9a-8474a3de12bc
2025-05-02 18:52:41,280 [ERROR] Error processing LinkedIn profile: 1 validation error for LinkedInProfile
full_name
  Field required [type=missing, input_value={'error': 'API request fa...n.com/in/dmn-sangeeth/'}, input_type=dict]
    For further information visit https://errors.pydantic.dev/2.9/v/missing
2025-05-02 18:52:41,280 [ERROR] Error processing LinkedIn profile: Profile processing failed: 1 validation error for LinkedInProfile
full_name
  Field required [type=missing, input_value={'error': 'API request fa...n.com/in/dmn-sangeeth/'}, input_type=dict]
    For further information visit https://errors.pydantic.dev/2.9/v/missing
Traceback (most recent call last):
  File "/home/dmnsangeeth/Desktop/project/ai-recruitment-platform/app/services/linkedin_service.py", line 119, in scraping_linkedin_content
    profile = LinkedInProfile(**profile_data)
  File "/home/dmnsangeeth/anaconda3/envs/gemini/lib/python3.13/site-packages/pydantic/main.py", line 212, in __init__
    validated_self = self.__pydantic_validator__.validate_python(data, self_instance=self)
pydantic_core._pydantic_core.ValidationError: 1 validation error for LinkedInProfile
full_name
  Field required [type=missing, input_value={'error': 'API request fa...n.com/in/dmn-sangeeth/'}, input_type=dict]
    For further information visit https://errors.pydantic.dev/2.9/v/missing

During handling of the above exception, another exception occurred:

Traceback (most recent call last):
  File "/home/dmnsangeeth/Desktop/project/ai-recruitment-platform/app/api/v1/endpoints/linkedin.py", line 46, in upload_linkedin_profile
    profile_data = await linkedin_service.scraping_linkedin_content(
                   ^^^^^^^^^^^^^^^^^^^^^^^^^^^^^^^^^^^^^^^^^^^^^^^^^
        linkedin_url=str(linkedin_url))
        ^^^^^^^^^^^^^^^^^^^^^^^^^^^^^^^
  File "/home/dmnsangeeth/Desktop/project/ai-recruitment-platform/app/services/linkedin_service.py", line 128, in scraping_linkedin_content
    raise ProfileProcessingError(f"Profile processing failed: {str(e)}")
app.utils.exceptions.ProfileProcessingError: Profile processing failed: 1 validation error for LinkedInProfile
full_name
  Field required [type=missing, input_value={'error': 'API request fa...n.com/in/dmn-sangeeth/'}, input_type=dict]
    For further information visit https://errors.pydantic.dev/2.9/v/missing
2025-05-02 18:52:50,186 [ERROR] API request failed: 403 Client Error: Forbidden for url: https://api-f1db6c.stack.tryrelevance.com/latest/studios/d58d3b72-d349-44f4-b5f9-9f03f090fa7a/trigger_webhook?project=8f40138a7b22-4b6d-8b9a-8474a3de12bc
2025-05-02 18:52:50,187 [ERROR] Error processing LinkedIn profile: 1 validation error for LinkedInProfile
full_name
  Field required [type=missing, input_value={'error': 'API request fa...in.com/in/dmn-sangeeth'}, input_type=dict]
    For further information visit https://errors.pydantic.dev/2.9/v/missing
2025-05-02 18:52:50,187 [ERROR] Error processing LinkedIn profile: Profile processing failed: 1 validation error for LinkedInProfile
full_name
  Field required [type=missing, input_value={'error': 'API request fa...in.com/in/dmn-sangeeth'}, input_type=dict]
    For further information visit https://errors.pydantic.dev/2.9/v/missing
Traceback (most recent call last):
  File "/home/dmnsangeeth/Desktop/project/ai-recruitment-platform/app/services/linkedin_service.py", line 119, in scraping_linkedin_content
    profile = LinkedInProfile(**profile_data)
  File "/home/dmnsangeeth/anaconda3/envs/gemini/lib/python3.13/site-packages/pydantic/main.py", line 212, in __init__
    validated_self = self.__pydantic_validator__.validate_python(data, self_instance=self)
pydantic_core._pydantic_core.ValidationError: 1 validation error for LinkedInProfile
full_name
  Field required [type=missing, input_value={'error': 'API request fa...in.com/in/dmn-sangeeth'}, input_type=dict]
    For further information visit https://errors.pydantic.dev/2.9/v/missing

During handling of the above exception, another exception occurred:

Traceback (most recent call last):
  File "/home/dmnsangeeth/Desktop/project/ai-recruitment-platform/app/api/v1/endpoints/linkedin.py", line 46, in upload_linkedin_profile
    profile_data = await linkedin_service.scraping_linkedin_content(
                   ^^^^^^^^^^^^^^^^^^^^^^^^^^^^^^^^^^^^^^^^^^^^^^^^^
        linkedin_url=str(linkedin_url))
        ^^^^^^^^^^^^^^^^^^^^^^^^^^^^^^^
  File "/home/dmnsangeeth/Desktop/project/ai-recruitment-platform/app/services/linkedin_service.py", line 128, in scraping_linkedin_content
    raise ProfileProcessingError(f"Profile processing failed: {str(e)}")
app.utils.exceptions.ProfileProcessingError: Profile processing failed: 1 validation error for LinkedInProfile
full_name
  Field required [type=missing, input_value={'error': 'API request fa...in.com/in/dmn-sangeeth'}, input_type=dict]
    For further information visit https://errors.pydantic.dev/2.9/v/missing
2025-05-02 19:00:27,728 [INFO] Embedding generator initialized successfully
2025-05-02 19:00:27,821 [INFO] Embedding generator initialized successfully
2025-05-02 19:01:04,358 [ERROR] API request failed: 403 Client Error: Forbidden for url: https://api-f1db6c.stack.tryrelevance.com/latest/studios/d58d3b72-d349-44f4-b5f9-9f03f090fa7a/trigger_webhook?project=8f40138a7b22-4b6d-8b9a-8474a3de12bc
2025-05-02 19:01:04,359 [ERROR] Error processing LinkedIn profile: 1 validation error for LinkedInProfile
full_name
  Field required [type=missing, input_value={'error': 'API request fa...in.com/in/dmn-sangeeth'}, input_type=dict]
    For further information visit https://errors.pydantic.dev/2.9/v/missing
2025-05-02 19:01:04,359 [ERROR] Error processing LinkedIn profile: Profile processing failed: 1 validation error for LinkedInProfile
full_name
  Field required [type=missing, input_value={'error': 'API request fa...in.com/in/dmn-sangeeth'}, input_type=dict]
    For further information visit https://errors.pydantic.dev/2.9/v/missing
Traceback (most recent call last):
  File "/home/dmnsangeeth/Desktop/project/ai-recruitment-platform/app/services/linkedin_service.py", line 119, in scraping_linkedin_content
    profile = LinkedInProfile(**profile_data)
  File "/home/dmnsangeeth/anaconda3/envs/gemini/lib/python3.13/site-packages/pydantic/main.py", line 212, in __init__
    validated_self = self.__pydantic_validator__.validate_python(data, self_instance=self)
pydantic_core._pydantic_core.ValidationError: 1 validation error for LinkedInProfile
full_name
  Field required [type=missing, input_value={'error': 'API request fa...in.com/in/dmn-sangeeth'}, input_type=dict]
    For further information visit https://errors.pydantic.dev/2.9/v/missing

During handling of the above exception, another exception occurred:

Traceback (most recent call last):
  File "/home/dmnsangeeth/Desktop/project/ai-recruitment-platform/app/api/v1/endpoints/linkedin.py", line 46, in upload_linkedin_profile
    profile_data = await linkedin_service.scraping_linkedin_content(
                   ^^^^^^^^^^^^^^^^^^^^^^^^^^^^^^^^^^^^^^^^^^^^^^^^^
        linkedin_url=str(linkedin_url))
        ^^^^^^^^^^^^^^^^^^^^^^^^^^^^^^^
  File "/home/dmnsangeeth/Desktop/project/ai-recruitment-platform/app/services/linkedin_service.py", line 128, in scraping_linkedin_content
    raise ProfileProcessingError(f"Profile processing failed: {str(e)}")
app.utils.exceptions.ProfileProcessingError: Profile processing failed: 1 validation error for LinkedInProfile
full_name
  Field required [type=missing, input_value={'error': 'API request fa...in.com/in/dmn-sangeeth'}, input_type=dict]
    For further information visit https://errors.pydantic.dev/2.9/v/missing
2025-05-02 19:03:53,286 [INFO] Embedding generator initialized successfully
2025-05-02 19:03:53,430 [INFO] Embedding generator initialized successfully
2025-05-02 19:03:56,282 [ERROR] API request failed: 403 Client Error: Forbidden for url: https://api-f1db6c.stack.tryrelevance.com/latest/studios/d58d3b72-d349-44f4-b5f9-9f03f090fa7a/trigger_webhook?project=8f40138a7b22-4b6d-8b9a-8474a3de12bc
2025-05-02 19:03:56,282 [ERROR] Error processing LinkedIn profile: 1 validation error for LinkedInProfile
full_name
  Field required [type=missing, input_value={'error': 'API request fa...in.com/in/dmn-sangeeth'}, input_type=dict]
    For further information visit https://errors.pydantic.dev/2.9/v/missing
2025-05-02 19:03:56,282 [ERROR] Error processing LinkedIn profile: Profile processing failed: 1 validation error for LinkedInProfile
full_name
  Field required [type=missing, input_value={'error': 'API request fa...in.com/in/dmn-sangeeth'}, input_type=dict]
    For further information visit https://errors.pydantic.dev/2.9/v/missing
Traceback (most recent call last):
  File "/home/dmnsangeeth/Desktop/project/ai-recruitment-platform/app/services/linkedin_service.py", line 119, in scraping_linkedin_content
    profile = LinkedInProfile(**profile_data)
  File "/home/dmnsangeeth/anaconda3/envs/gemini/lib/python3.13/site-packages/pydantic/main.py", line 212, in __init__
    validated_self = self.__pydantic_validator__.validate_python(data, self_instance=self)
pydantic_core._pydantic_core.ValidationError: 1 validation error for LinkedInProfile
full_name
  Field required [type=missing, input_value={'error': 'API request fa...in.com/in/dmn-sangeeth'}, input_type=dict]
    For further information visit https://errors.pydantic.dev/2.9/v/missing

During handling of the above exception, another exception occurred:

Traceback (most recent call last):
  File "/home/dmnsangeeth/Desktop/project/ai-recruitment-platform/app/api/v1/endpoints/linkedin.py", line 46, in upload_linkedin_profile
    profile_data = await linkedin_service.scraping_linkedin_content(
                   ^^^^^^^^^^^^^^^^^^^^^^^^^^^^^^^^^^^^^^^^^^^^^^^^^
        linkedin_url=str(linkedin_url))
        ^^^^^^^^^^^^^^^^^^^^^^^^^^^^^^^
  File "/home/dmnsangeeth/Desktop/project/ai-recruitment-platform/app/services/linkedin_service.py", line 128, in scraping_linkedin_content
    raise ProfileProcessingError(f"Profile processing failed: {str(e)}")
app.utils.exceptions.ProfileProcessingError: Profile processing failed: 1 validation error for LinkedInProfile
full_name
  Field required [type=missing, input_value={'error': 'API request fa...in.com/in/dmn-sangeeth'}, input_type=dict]
    For further information visit https://errors.pydantic.dev/2.9/v/missing
2025-05-02 19:11:15,000 [INFO] Embedding generator initialized successfully
2025-05-02 19:11:15,079 [INFO] Embedding generator initialized successfully
2025-05-02 19:12:31,910 [INFO] Embedding generator initialized successfully
2025-05-02 19:12:31,984 [INFO] Embedding generator initialized successfully
2025-05-02 19:12:54,554 [ERROR] API request failed: 403 Client Error: Forbidden for url: https://api-f1db6c.stack.tryrelevance.com/latest/studios/d58d3b72-d349-44f4-b5f9-9f03f090fa7a/trigger_webhook?project=8f40138a7b22-4b6d-8b9a-8474a3de12bc
2025-05-02 19:12:54,555 [ERROR] Error processing LinkedIn profile: 1 validation error for LinkedInProfile
full_name
  Field required [type=missing, input_value={'error': 'API request fa...in.com/in/dmn-sangeeth'}, input_type=dict]
    For further information visit https://errors.pydantic.dev/2.9/v/missing
2025-05-02 19:12:54,555 [ERROR] Error processing LinkedIn profile: Profile processing failed: 1 validation error for LinkedInProfile
full_name
  Field required [type=missing, input_value={'error': 'API request fa...in.com/in/dmn-sangeeth'}, input_type=dict]
    For further information visit https://errors.pydantic.dev/2.9/v/missing
Traceback (most recent call last):
  File "/home/dmnsangeeth/Desktop/project/ai-recruitment-platform/app/services/linkedin_service.py", line 120, in scraping_linkedin_content
    profile = LinkedInProfile(**profile_data)
  File "/home/dmnsangeeth/anaconda3/envs/gemini/lib/python3.13/site-packages/pydantic/main.py", line 212, in __init__
    validated_self = self.__pydantic_validator__.validate_python(data, self_instance=self)
pydantic_core._pydantic_core.ValidationError: 1 validation error for LinkedInProfile
full_name
  Field required [type=missing, input_value={'error': 'API request fa...in.com/in/dmn-sangeeth'}, input_type=dict]
    For further information visit https://errors.pydantic.dev/2.9/v/missing

During handling of the above exception, another exception occurred:

Traceback (most recent call last):
  File "/home/dmnsangeeth/Desktop/project/ai-recruitment-platform/app/api/v1/endpoints/linkedin.py", line 46, in upload_linkedin_profile
    profile_data = await linkedin_service.scraping_linkedin_content(
                   ^^^^^^^^^^^^^^^^^^^^^^^^^^^^^^^^^^^^^^^^^^^^^^^^^
        linkedin_url=str(linkedin_url))
        ^^^^^^^^^^^^^^^^^^^^^^^^^^^^^^^
  File "/home/dmnsangeeth/Desktop/project/ai-recruitment-platform/app/services/linkedin_service.py", line 129, in scraping_linkedin_content
    raise ProfileProcessingError(f"Profile processing failed: {str(e)}")
app.utils.exceptions.ProfileProcessingError: Profile processing failed: 1 validation error for LinkedInProfile
full_name
  Field required [type=missing, input_value={'error': 'API request fa...in.com/in/dmn-sangeeth'}, input_type=dict]
    For further information visit https://errors.pydantic.dev/2.9/v/missing
2025-05-02 19:13:33,558 [INFO] Embedding generator initialized successfully
2025-05-02 19:13:33,682 [INFO] Embedding generator initialized successfully
2025-05-02 19:13:40,720 [INFO] Embedding generator initialized successfully
2025-05-02 19:13:40,830 [INFO] Embedding generator initialized successfully
2025-05-02 19:14:02,687 [ERROR] API request failed: 403 Client Error: Forbidden for url: https://api-f1db6c.stack.tryrelevance.com/latest/studios/d58d3b72-d349-44f4-b5f9-9f03f090fa7a/trigger_webhook?project=8f40138a7b22-4b6d-8b9a-8474a3de12bc
2025-05-02 19:14:02,688 [ERROR] Error processing LinkedIn profile: 1 validation error for LinkedInProfile
full_name
  Field required [type=missing, input_value={'error': 'API request fa...n.com/in/dmn-sangeeth/'}, input_type=dict]
    For further information visit https://errors.pydantic.dev/2.9/v/missing
2025-05-02 19:14:02,689 [ERROR] Error processing LinkedIn profile: Profile processing failed: 1 validation error for LinkedInProfile
full_name
  Field required [type=missing, input_value={'error': 'API request fa...n.com/in/dmn-sangeeth/'}, input_type=dict]
    For further information visit https://errors.pydantic.dev/2.9/v/missing
Traceback (most recent call last):
  File "/home/dmnsangeeth/Desktop/project/ai-recruitment-platform/app/services/linkedin_service.py", line 120, in scraping_linkedin_content
    profile = LinkedInProfile(**profile_data)
  File "/home/dmnsangeeth/anaconda3/envs/gemini/lib/python3.13/site-packages/pydantic/main.py", line 212, in __init__
    validated_self = self.__pydantic_validator__.validate_python(data, self_instance=self)
pydantic_core._pydantic_core.ValidationError: 1 validation error for LinkedInProfile
full_name
  Field required [type=missing, input_value={'error': 'API request fa...n.com/in/dmn-sangeeth/'}, input_type=dict]
    For further information visit https://errors.pydantic.dev/2.9/v/missing

During handling of the above exception, another exception occurred:

Traceback (most recent call last):
  File "/home/dmnsangeeth/Desktop/project/ai-recruitment-platform/app/api/v1/endpoints/linkedin.py", line 46, in upload_linkedin_profile
    profile_data = await linkedin_service.scraping_linkedin_content(
                   ^^^^^^^^^^^^^^^^^^^^^^^^^^^^^^^^^^^^^^^^^^^^^^^^^
        linkedin_url=str(linkedin_url))
        ^^^^^^^^^^^^^^^^^^^^^^^^^^^^^^^
  File "/home/dmnsangeeth/Desktop/project/ai-recruitment-platform/app/services/linkedin_service.py", line 129, in scraping_linkedin_content
    raise ProfileProcessingError(f"Profile processing failed: {str(e)}")
app.utils.exceptions.ProfileProcessingError: Profile processing failed: 1 validation error for LinkedInProfile
full_name
  Field required [type=missing, input_value={'error': 'API request fa...n.com/in/dmn-sangeeth/'}, input_type=dict]
    For further information visit https://errors.pydantic.dev/2.9/v/missing
2025-05-02 19:17:22,620 [INFO] Embedding generator initialized successfully
2025-05-02 19:17:22,798 [INFO] Embedding generator initialized successfully
2025-05-02 19:17:28,285 [INFO] Embedding generator initialized successfully
2025-05-02 19:17:28,396 [INFO] Embedding generator initialized successfully
2025-05-02 19:17:29,193 [ERROR] API request failed: 403 Client Error: Forbidden for url: https://api-f1db6c.stack.tryrelevance.com/latest/studios/d58d3b72-d349-44f4-b5f9-9f03f090fa7a/trigger_webhook?project=8f40138a7b22-4b6d-8b9a-8474a3de12bc
2025-05-02 19:17:29,194 [ERROR] Error processing LinkedIn profile: 1 validation error for LinkedInProfile
full_name
  Field required [type=missing, input_value={'error': 'API request fa...n.com/in/dmn-sangeeth/'}, input_type=dict]
    For further information visit https://errors.pydantic.dev/2.9/v/missing
2025-05-02 19:17:29,194 [ERROR] Error processing LinkedIn profile: Profile processing failed: 1 validation error for LinkedInProfile
full_name
  Field required [type=missing, input_value={'error': 'API request fa...n.com/in/dmn-sangeeth/'}, input_type=dict]
    For further information visit https://errors.pydantic.dev/2.9/v/missing
Traceback (most recent call last):
  File "/home/dmnsangeeth/Desktop/project/ai-recruitment-platform/app/services/linkedin_service.py", line 121, in scraping_linkedin_content
    profile = LinkedInProfile(**profile_data)
  File "/home/dmnsangeeth/anaconda3/envs/gemini/lib/python3.13/site-packages/pydantic/main.py", line 212, in __init__
    validated_self = self.__pydantic_validator__.validate_python(data, self_instance=self)
pydantic_core._pydantic_core.ValidationError: 1 validation error for LinkedInProfile
full_name
  Field required [type=missing, input_value={'error': 'API request fa...n.com/in/dmn-sangeeth/'}, input_type=dict]
    For further information visit https://errors.pydantic.dev/2.9/v/missing

During handling of the above exception, another exception occurred:

Traceback (most recent call last):
  File "/home/dmnsangeeth/Desktop/project/ai-recruitment-platform/app/api/v1/endpoints/linkedin.py", line 46, in upload_linkedin_profile
    profile_data = await linkedin_service.scraping_linkedin_content(
                   ^^^^^^^^^^^^^^^^^^^^^^^^^^^^^^^^^^^^^^^^^^^^^^^^^
        linkedin_url=str(linkedin_url))
        ^^^^^^^^^^^^^^^^^^^^^^^^^^^^^^^
  File "/home/dmnsangeeth/Desktop/project/ai-recruitment-platform/app/services/linkedin_service.py", line 130, in scraping_linkedin_content
    raise ProfileProcessingError(f"Profile processing failed: {str(e)}")
app.utils.exceptions.ProfileProcessingError: Profile processing failed: 1 validation error for LinkedInProfile
full_name
  Field required [type=missing, input_value={'error': 'API request fa...n.com/in/dmn-sangeeth/'}, input_type=dict]
    For further information visit https://errors.pydantic.dev/2.9/v/missing
2025-05-02 19:24:42,693 [INFO] Embedding generator initialized successfully
2025-05-02 19:24:42,806 [INFO] Embedding generator initialized successfully
2025-05-02 19:27:32,377 [INFO] Embedding generator initialized successfully
2025-05-02 19:27:32,466 [INFO] Embedding generator initialized successfully
2025-05-02 19:28:07,936 [INFO] Embedding generator initialized successfully
2025-05-02 19:28:08,044 [INFO] Embedding generator initialized successfully
2025-05-02 19:29:32,870 [INFO] File saved at: storage/resumes/resume_20250502_192932.png
2025-05-02 19:29:33,989 [INFO] HTTP Request: POST https://generativelanguage.googleapis.com/upload/v1beta/files "HTTP/1.1 200 OK"
2025-05-02 19:29:46,789 [INFO] HTTP Request: POST https://generativelanguage.googleapis.com/upload/v1beta/files?upload_id=AAO2Vwrt0cecmIYprXYbDV1UjZ7oVOjjBo-jm_Km4LV9a59lx-ZgryEkS2D0z8J1qq1S3sOvsqbi18SHVr2T5Fhvht0oJXU9wHeUsCJkpxoYTg&upload_protocol=resumable "HTTP/1.1 200 OK"
2025-05-02 19:29:46,790 [INFO] AFC is enabled with max remote calls: 10.
2025-05-02 19:29:51,398 [INFO] HTTP Request: POST https://generativelanguage.googleapis.com/v1beta/models/gemini-2.0-flash:generateContent "HTTP/1.1 200 OK"
2025-05-02 19:29:51,399 [INFO] AFC remote call 1 is done.
2025-05-02 19:30:00,415 [INFO] Successfully created embedding for resume: NISHAN SANGEETH
2025-05-02 19:30:02,208 [INFO] Successfully processed and stored resume for NISHAN SANGEETH
2025-05-02 19:30:03,224 [INFO] Successfully created embedding for resume: None
2025-05-02 19:30:19,124 [INFO] Embedding generator initialized successfully
2025-05-02 19:30:19,183 [INFO] Embedding generator initialized successfully
2025-05-02 19:30:25,544 [INFO] File saved at: storage/resumes/resume_20250502_193025.png
2025-05-02 19:30:26,318 [INFO] HTTP Request: POST https://generativelanguage.googleapis.com/upload/v1beta/files "HTTP/1.1 200 OK"
2025-05-02 19:30:33,581 [INFO] HTTP Request: POST https://generativelanguage.googleapis.com/upload/v1beta/files?upload_id=AAO2Vwrc8O8pEdpAOOXPPy7JjXgUjoqf63Mn2ZyG7hk0w6Az-Rbsyy1lfyNbNFzpWiSwedxCVkjXpkXg50FwBxqG8U2AdMpFO_-dZPrvlLlDVg&upload_protocol=resumable "HTTP/1.1 200 OK"
2025-05-02 19:30:33,582 [INFO] AFC is enabled with max remote calls: 10.
2025-05-02 19:30:37,739 [INFO] HTTP Request: POST https://generativelanguage.googleapis.com/v1beta/models/gemini-2.0-flash:generateContent "HTTP/1.1 200 OK"
2025-05-02 19:30:37,741 [INFO] AFC remote call 1 is done.
2025-05-02 19:30:46,086 [INFO] Successfully created embedding for resume: NISHAN SANGEETH
2025-05-02 19:30:47,471 [INFO] Successfully processed and stored resume for NISHAN SANGEETH
2025-05-02 19:30:48,032 [INFO] Successfully created embedding for resume: None
2025-05-02 20:17:12,461 [INFO] Embedding generator initialized successfully
2025-05-02 20:17:12,543 [INFO] Embedding generator initialized successfully
2025-05-02 20:40:09,317 [INFO] Embedding generator initialized successfully
2025-05-02 20:40:09,377 [INFO] Embedding generator initialized successfully
2025-05-02 20:40:22,803 [INFO] Embedding generator initialized successfully
2025-05-02 20:40:22,887 [INFO] Embedding generator initialized successfully
2025-05-02 20:46:15,735 [INFO] Embedding generator initialized successfully
2025-05-02 20:46:15,790 [INFO] Embedding generator initialized successfully
2025-05-02 20:46:15,793 [INFO] Embedding generator initialized successfully
2025-05-02 20:46:15,828 [INFO] Embedding generator initialized successfully
2025-05-02 20:46:26,619 [INFO] Embedding generator initialized successfully
2025-05-02 20:46:26,706 [INFO] Embedding generator initialized successfully
2025-05-02 20:46:26,710 [INFO] Embedding generator initialized successfully
2025-05-02 20:46:26,762 [INFO] Embedding generator initialized successfully
2025-05-02 20:46:51,961 [INFO] Embedding generator initialized successfully
2025-05-02 20:46:52,019 [INFO] Embedding generator initialized successfully
2025-05-02 20:46:52,023 [INFO] Embedding generator initialized successfully
2025-05-02 20:46:52,059 [INFO] Embedding generator initialized successfully
2025-05-02 20:47:08,244 [INFO] File saved at: storage/resumes/resume_20250502_204708.png
2025-05-02 20:47:09,243 [INFO] HTTP Request: POST https://generativelanguage.googleapis.com/upload/v1beta/files "HTTP/1.1 200 OK"
2025-05-02 20:47:17,128 [INFO] HTTP Request: POST https://generativelanguage.googleapis.com/upload/v1beta/files?upload_id=AAO2VwpVG_PWLEyYgalgw9c_MdHk3OOQnxraBi-TYmyM2DVGSyxkyp4nB7UZRJ1AhSPE2vQqLta6QRq6YbmlaPuAg78PqZa0ckgouI3XfZIhK28&upload_protocol=resumable "HTTP/1.1 200 OK"
2025-05-02 20:47:17,128 [INFO] AFC is enabled with max remote calls: 10.
2025-05-02 20:47:21,941 [INFO] HTTP Request: POST https://generativelanguage.googleapis.com/v1beta/models/gemini-2.0-flash:generateContent "HTTP/1.1 200 OK"
2025-05-02 20:47:21,945 [INFO] AFC remote call 1 is done.
2025-05-02 20:47:31,684 [INFO] Successfully created embedding for resume: NISHAN SANGEETH
2025-05-02 20:47:33,144 [INFO] Successfully processed and stored resume for NISHAN SANGEETH
2025-05-02 20:47:33,628 [INFO] Successfully created embedding for resume: None
2025-05-02 20:48:02,391 [WARNING] Invalid resume detected: The provided text is a structured data representation of a LinkedIn profile, not a resume in a human-readable format. While it contains information typically found in a resume (name, work experience, skills implicitly through descriptions), it's presented in a machine-readable format using Python's ObjectId, datetime objects, and other data structures.  A true resume would be formatted for human consumption, typically in a document (e.g., .doc, .pdf)  with clear section headings and a visually appealing layout.
2025-05-02 20:48:02,905 [INFO] Successfully created embedding for resume: None
2025-05-02 20:58:50,529 [INFO] Embedding generator initialized successfully
2025-05-02 20:58:50,587 [INFO] Embedding generator initialized successfully
2025-05-02 20:58:50,592 [INFO] Embedding generator initialized successfully
2025-05-02 20:58:50,630 [INFO] Embedding generator initialized successfully
2025-05-02 20:59:38,698 [INFO] Embedding generator initialized successfully
2025-05-02 20:59:38,753 [INFO] Embedding generator initialized successfully
2025-05-02 20:59:38,757 [INFO] Embedding generator initialized successfully
2025-05-02 20:59:38,794 [INFO] Embedding generator initialized successfully
2025-05-02 21:03:19,848 [INFO] Embedding generator initialized successfully
2025-05-02 21:03:19,913 [INFO] Embedding generator initialized successfully
2025-05-02 21:03:19,917 [INFO] Embedding generator initialized successfully
2025-05-02 21:03:19,949 [INFO] Embedding generator initialized successfully
2025-05-02 21:03:58,724 [ERROR] JSON Decode Error: Expecting value: line 1 column 1 (char 0)
Traceback (most recent call last):
  File "/home/dmnsangeeth/Desktop/project/ai-recruitment-platform/app/utils/helpers.py", line 21, in extract_and_validate_json
    json.loads(cleaned_text)
    ~~~~~~~~~~^^^^^^^^^^^^^^
  File "/home/dmnsangeeth/anaconda3/envs/gemini/lib/python3.13/json/__init__.py", line 346, in loads
    return _default_decoder.decode(s)
           ~~~~~~~~~~~~~~~~~~~~~~~^^^
  File "/home/dmnsangeeth/anaconda3/envs/gemini/lib/python3.13/json/decoder.py", line 345, in decode
    obj, end = self.raw_decode(s, idx=_w(s, 0).end())
               ~~~~~~~~~~~~~~~^^^^^^^^^^^^^^^^^^^^^^^
  File "/home/dmnsangeeth/anaconda3/envs/gemini/lib/python3.13/json/decoder.py", line 363, in raw_decode
    raise JSONDecodeError("Expecting value", s, err.value) from None
json.decoder.JSONDecodeError: Expecting value: line 1 column 1 (char 0)
2025-05-02 21:03:58,729 [ERROR] Invalid JSON content extracted from resume
2025-05-02 21:03:58,729 [ERROR] Failed to process resume data
2025-05-02 21:03:59,237 [INFO] Successfully created embedding for resume: None
2025-05-02 21:05:28,523 [INFO] Embedding generator initialized successfully
2025-05-02 21:05:28,610 [INFO] Embedding generator initialized successfully
2025-05-02 21:05:28,616 [INFO] Embedding generator initialized successfully
2025-05-02 21:05:28,665 [INFO] Embedding generator initialized successfully
2025-05-02 21:05:58,827 [INFO] Embedding generator initialized successfully
2025-05-02 21:05:58,896 [INFO] Embedding generator initialized successfully
2025-05-02 21:05:58,899 [INFO] Embedding generator initialized successfully
2025-05-02 21:05:58,940 [INFO] Embedding generator initialized successfully
2025-05-02 21:06:48,199 [ERROR] Error processing resume: ResumeService.process_resume_data() got an unexpected keyword argument 'resume_text'
Traceback (most recent call last):
  File "/home/dmnsangeeth/Desktop/project/ai-recruitment-platform/app/api/v1/endpoints/linkedin.py", line 54, in upload_linkedin_profile
    resume_data = await resume_service.process_resume_data(resume_text=profile_data)
                        ~~~~~~~~~~~~~~~~~~~~~~~~~~~~~~~~~~^^^^^^^^^^^^^^^^^^^^^^^^^^
TypeError: ResumeService.process_resume_data() got an unexpected keyword argument 'resume_text'
2025-05-02 21:07:41,340 [INFO] Embedding generator initialized successfully
2025-05-02 21:07:41,425 [INFO] Embedding generator initialized successfully
2025-05-02 21:07:41,430 [INFO] Embedding generator initialized successfully
2025-05-02 21:07:41,483 [INFO] Embedding generator initialized successfully
2025-05-02 21:07:57,732 [INFO] Successfully created embedding for resume: DMN Sangeeth
2025-05-02 21:07:57,732 [ERROR] Error processing resume: 2 validation errors for Resume
email
  Input should be a valid string [type=string_type, input_value=None, input_type=NoneType]
    For further information visit https://errors.pydantic.dev/2.9/v/string_type
phone
  Input should be a valid string [type=string_type, input_value=None, input_type=NoneType]
    For further information visit https://errors.pydantic.dev/2.9/v/string_type
2025-05-02 21:07:57,732 [ERROR] Failed to process resume data
2025-05-02 21:07:59,268 [INFO] Successfully created embedding for resume: None
2025-05-02 21:10:18,096 [INFO] Embedding generator initialized successfully
2025-05-02 21:10:18,186 [INFO] Embedding generator initialized successfully
2025-05-02 21:10:18,190 [INFO] Embedding generator initialized successfully
2025-05-02 21:10:18,226 [INFO] Embedding generator initialized successfully
2025-05-02 21:11:01,520 [INFO] Embedding generator initialized successfully
2025-05-02 21:11:01,604 [INFO] Embedding generator initialized successfully
2025-05-02 21:11:01,610 [INFO] Embedding generator initialized successfully
2025-05-02 21:11:01,665 [INFO] Embedding generator initialized successfully
2025-05-02 21:11:04,758 [INFO] Embedding generator initialized successfully
2025-05-02 21:11:04,816 [INFO] Embedding generator initialized successfully
2025-05-02 21:11:04,820 [INFO] Embedding generator initialized successfully
2025-05-02 21:11:04,859 [INFO] Embedding generator initialized successfully
2025-05-02 21:11:22,392 [INFO] Embedding generator initialized successfully
2025-05-02 21:11:22,451 [INFO] Embedding generator initialized successfully
2025-05-02 21:11:22,454 [INFO] Embedding generator initialized successfully
2025-05-02 21:11:22,490 [INFO] Embedding generator initialized successfully
2025-05-02 21:32:50,853 [WARNING] Invalid resume detected: The provided text is not a resume in its presented format.  While it contains resume-like data such as name, work experience, and skills (although embedded in a non-standard way), the structure is that of a database record or JSON representation of a person's profile.  It lacks the typical formatting and presentation of a human-readable resume. Key elements such as contact information are missing or incomplete ('email=None', 'phone=None').  The data is structured for machine processing, not direct human consumption as a resume.
2025-05-02 21:32:51,386 [INFO] Successfully created embedding for resume: None
2025-05-02 22:48:28,958 [INFO] Embedding generator initialized successfully
2025-05-02 22:48:29,013 [INFO] Embedding generator initialized successfully
2025-05-02 22:48:29,017 [INFO] Embedding generator initialized successfully
2025-05-02 22:48:29,049 [INFO] Embedding generator initialized successfully
2025-05-02 22:49:41,521 [INFO] Embedding generator initialized successfully
2025-05-02 22:49:41,578 [INFO] Embedding generator initialized successfully
2025-05-02 22:49:41,581 [INFO] Embedding generator initialized successfully
2025-05-02 22:49:41,617 [INFO] Embedding generator initialized successfully
2025-05-02 22:53:32,275 [INFO] Embedding generator initialized successfully
2025-05-02 22:53:32,355 [INFO] Embedding generator initialized successfully
2025-05-02 22:53:32,359 [INFO] Embedding generator initialized successfully
2025-05-02 22:53:32,409 [INFO] Embedding generator initialized successfully
2025-05-02 22:53:35,296 [INFO] Embedding generator initialized successfully
2025-05-02 22:53:35,353 [INFO] Embedding generator initialized successfully
2025-05-02 22:53:35,357 [INFO] Embedding generator initialized successfully
2025-05-02 22:53:35,392 [INFO] Embedding generator initialized successfully
2025-05-02 22:54:02,926 [INFO] Embedding generator initialized successfully
2025-05-02 22:54:02,981 [INFO] Embedding generator initialized successfully
2025-05-02 22:54:02,985 [INFO] Embedding generator initialized successfully
2025-05-02 22:54:03,018 [INFO] Embedding generator initialized successfully
2025-05-02 22:56:59,196 [INFO] Embedding generator initialized successfully
2025-05-02 22:56:59,293 [INFO] Embedding generator initialized successfully
2025-05-02 22:56:59,297 [INFO] Embedding generator initialized successfully
2025-05-02 22:56:59,335 [INFO] Embedding generator initialized successfully
2025-05-02 22:57:38,792 [INFO] Embedding generator initialized successfully
2025-05-02 22:57:38,852 [INFO] Embedding generator initialized successfully
2025-05-02 22:57:38,856 [INFO] Embedding generator initialized successfully
2025-05-02 22:57:38,892 [INFO] Embedding generator initialized successfully
2025-05-02 22:58:26,790 [INFO] Embedding generator initialized successfully
2025-05-02 22:58:26,843 [INFO] Embedding generator initialized successfully
2025-05-02 22:58:26,846 [INFO] Embedding generator initialized successfully
2025-05-02 22:58:26,879 [INFO] Embedding generator initialized successfully
2025-05-02 22:58:39,822 [INFO] Embedding generator initialized successfully
2025-05-02 22:58:39,903 [INFO] Embedding generator initialized successfully
2025-05-02 22:58:39,908 [INFO] Embedding generator initialized successfully
2025-05-02 22:58:39,957 [INFO] Embedding generator initialized successfully
2025-05-02 23:01:07,467 [INFO] Embedding generator initialized successfully
2025-05-02 23:01:07,526 [INFO] Embedding generator initialized successfully
2025-05-02 23:01:07,531 [INFO] Embedding generator initialized successfully
2025-05-02 23:01:07,567 [INFO] Embedding generator initialized successfully
2025-05-02 23:02:34,551 [INFO] Embedding generator initialized successfully
2025-05-02 23:02:34,611 [INFO] Embedding generator initialized successfully
2025-05-02 23:02:34,615 [INFO] Embedding generator initialized successfully
2025-05-02 23:02:34,649 [INFO] Embedding generator initialized successfully
2025-05-02 23:06:02,757 [INFO] Embedding generator initialized successfully
2025-05-02 23:06:02,840 [INFO] Embedding generator initialized successfully
2025-05-02 23:06:02,845 [INFO] Embedding generator initialized successfully
2025-05-02 23:06:02,895 [INFO] Embedding generator initialized successfully
2025-05-02 23:07:31,290 [INFO] Embedding generator initialized successfully
2025-05-02 23:07:31,382 [INFO] Embedding generator initialized successfully
2025-05-02 23:07:31,447 [INFO] Embedding generator initialized successfully
2025-05-02 23:07:31,455 [INFO] Embedding generator initialized successfully
2025-05-02 23:07:31,504 [INFO] Embedding generator initialized successfully
2025-05-02 23:07:34,418 [INFO] Embedding generator initialized successfully
2025-05-02 23:07:34,474 [INFO] Embedding generator initialized successfully
2025-05-02 23:07:34,509 [INFO] Embedding generator initialized successfully
2025-05-02 23:07:34,512 [INFO] Embedding generator initialized successfully
2025-05-02 23:07:34,547 [INFO] Embedding generator initialized successfully
2025-05-02 23:08:32,512 [ERROR] Error processing resume: 'ResumeService' object has no attribute 'process_resume_data'
Traceback (most recent call last):
  File "/home/dmnsangeeth/Desktop/project/ai-recruitment-platform/app/api/v1/endpoints/linkedin.py", line 54, in upload_linkedin_profile
    resume_data = await resume_service.process_resume_data(profile_data)
                        ^^^^^^^^^^^^^^^^^^^^^^^^^^^^^^^^^^
AttributeError: 'ResumeService' object has no attribute 'process_resume_data'. Did you mean: 'process_resume_bytes'?
2025-05-02 23:10:54,479 [INFO] Embedding generator initialized successfully
2025-05-02 23:10:54,534 [INFO] Embedding generator initialized successfully
2025-05-02 23:10:54,568 [INFO] Embedding generator initialized successfully
2025-05-02 23:10:54,572 [INFO] Embedding generator initialized successfully
2025-05-02 23:10:54,605 [INFO] Embedding generator initialized successfully
2025-05-02 23:10:59,627 [INFO] Embedding generator initialized successfully
2025-05-02 23:10:59,711 [INFO] Embedding generator initialized successfully
2025-05-02 23:10:59,762 [INFO] Embedding generator initialized successfully
2025-05-02 23:10:59,767 [INFO] Embedding generator initialized successfully
2025-05-02 23:10:59,818 [INFO] Embedding generator initialized successfully
2025-05-02 23:11:11,201 [WARNING] Invalid resume detected: The profile contains core elements like name, headline, and substantial work experience details.  While optional elements like a summary, skills, and contact information are missing or empty, this is not critical for basic profile validation.
2025-05-02 23:11:11,755 [INFO] Successfully created embedding for resume: None
2025-05-02 23:12:23,491 [INFO] Embedding generator initialized successfully
2025-05-02 23:12:23,580 [INFO] Embedding generator initialized successfully
2025-05-02 23:12:23,630 [INFO] Embedding generator initialized successfully
2025-05-02 23:12:23,635 [INFO] Embedding generator initialized successfully
2025-05-02 23:12:23,685 [INFO] Embedding generator initialized successfully
2025-05-02 23:12:29,075 [INFO] File saved at: storage/resumes/resume_20250502_231229.png
2025-05-02 23:12:30,592 [INFO] HTTP Request: POST https://generativelanguage.googleapis.com/upload/v1beta/files "HTTP/1.1 200 OK"
2025-05-02 23:12:37,760 [INFO] HTTP Request: POST https://generativelanguage.googleapis.com/upload/v1beta/files?upload_id=AAO2VwpCdNqsHtVSjk-v-78qu9qGfX2YeS-w2XqINFV4gnQGGFeE6HmETk6SpIYyz2U74xSKrbhWd2TVBCM2TcoNMO7jXGDAHPTGalTdgObpGw&upload_protocol=resumable "HTTP/1.1 200 OK"
2025-05-02 23:12:37,762 [INFO] AFC is enabled with max remote calls: 10.
2025-05-02 23:12:42,472 [INFO] HTTP Request: POST https://generativelanguage.googleapis.com/v1beta/models/gemini-2.0-flash:generateContent "HTTP/1.1 200 OK"
2025-05-02 23:12:42,475 [INFO] AFC remote call 1 is done.
2025-05-02 23:12:51,675 [INFO] Successfully created embedding for resume: NISHAN SANGEETH
2025-05-02 23:12:53,394 [INFO] Successfully processed and stored resume for NISHAN SANGEETH
2025-05-02 23:12:53,952 [INFO] Successfully created embedding for resume: None
2025-05-02 23:33:09,986 [INFO] Embedding generator initialized successfully
2025-05-02 23:33:10,040 [INFO] Embedding generator initialized successfully
2025-05-02 23:33:10,073 [INFO] Embedding generator initialized successfully
2025-05-02 23:33:10,076 [INFO] Embedding generator initialized successfully
2025-05-02 23:33:10,109 [INFO] Embedding generator initialized successfully
2025-05-02 23:33:47,855 [INFO] Embedding generator initialized successfully
2025-05-02 23:33:47,909 [INFO] Embedding generator initialized successfully
2025-05-02 23:33:47,943 [INFO] Embedding generator initialized successfully
2025-05-02 23:33:47,948 [INFO] Embedding generator initialized successfully
2025-05-02 23:33:47,982 [INFO] Embedding generator initialized successfully
2025-05-02 23:34:19,768 [INFO] Embedding generator initialized successfully
2025-05-02 23:34:19,828 [INFO] Embedding generator initialized successfully
2025-05-02 23:34:19,863 [INFO] Embedding generator initialized successfully
2025-05-02 23:34:19,867 [INFO] Embedding generator initialized successfully
2025-05-02 23:34:19,906 [INFO] Embedding generator initialized successfully
2025-05-02 23:35:26,500 [INFO] Embedding generator initialized successfully
2025-05-02 23:35:26,554 [INFO] Embedding generator initialized successfully
2025-05-02 23:35:26,586 [INFO] Embedding generator initialized successfully
2025-05-02 23:35:26,589 [INFO] Embedding generator initialized successfully
2025-05-02 23:35:26,620 [INFO] Embedding generator initialized successfully
2025-05-02 23:35:48,866 [ERROR] API request failed: 400 Client Error: Bad Request for url: https://api-f1db6c.stack.tryrelevance.com/latest/studios/d58d3b72-d349-44f4-b5f9-9f03f090fa7a/trigger_webhook?project=8f40138a7b22-4b6d-8b9a-8474a3de12bc
2025-05-02 23:35:48,868 [ERROR] Error processing LinkedIn profile: 1 validation error for LinkedInProfile
full_name
  Field required [type=missing, input_value={'error': 'API request fa...n.com/in/dmn-sangeeth/'}, input_type=dict]
    For further information visit https://errors.pydantic.dev/2.9/v/missing
2025-05-02 23:35:48,868 [ERROR] Error processing profile: Profile processing failed: 1 validation error for LinkedInProfile
full_name
  Field required [type=missing, input_value={'error': 'API request fa...n.com/in/dmn-sangeeth/'}, input_type=dict]
    For further information visit https://errors.pydantic.dev/2.9/v/missing
Traceback (most recent call last):
  File "/home/dmnsangeeth/Desktop/project/ai-recruitment-platform/app/services/linkedin_service.py", line 109, in scraping_linkedin_content
    profile = LinkedInProfile(**profile_data)
  File "/home/dmnsangeeth/anaconda3/envs/gemini/lib/python3.13/site-packages/pydantic/main.py", line 212, in __init__
    validated_self = self.__pydantic_validator__.validate_python(data, self_instance=self)
pydantic_core._pydantic_core.ValidationError: 1 validation error for LinkedInProfile
full_name
  Field required [type=missing, input_value={'error': 'API request fa...n.com/in/dmn-sangeeth/'}, input_type=dict]
    For further information visit https://errors.pydantic.dev/2.9/v/missing

During handling of the above exception, another exception occurred:

Traceback (most recent call last):
  File "/home/dmnsangeeth/Desktop/project/ai-recruitment-platform/app/api/v1/endpoints/linkedin.py", line 52, in upload_linkedin_profile
    profile_data = await linkedin_service.scraping_linkedin_content(
                   ^^^^^^^^^^^^^^^^^^^^^^^^^^^^^^^^^^^^^^^^^^^^^^^^^
        linkedin_url=str(linkedin_url))
        ^^^^^^^^^^^^^^^^^^^^^^^^^^^^^^^
  File "/home/dmnsangeeth/Desktop/project/ai-recruitment-platform/app/services/linkedin_service.py", line 118, in scraping_linkedin_content
    raise ProfileProcessingError(f"Profile processing failed: {str(e)}")
app.utils.exceptions.ProfileProcessingError: Profile processing failed: 1 validation error for LinkedInProfile
full_name
  Field required [type=missing, input_value={'error': 'API request fa...n.com/in/dmn-sangeeth/'}, input_type=dict]
    For further information visit https://errors.pydantic.dev/2.9/v/missing
2025-05-02 23:37:31,397 [INFO] Embedding generator initialized successfully
2025-05-02 23:37:31,454 [INFO] Embedding generator initialized successfully
2025-05-02 23:37:31,492 [INFO] Embedding generator initialized successfully
2025-05-02 23:37:31,496 [INFO] Embedding generator initialized successfully
2025-05-02 23:37:31,528 [INFO] Embedding generator initialized successfully
2025-05-02 23:37:48,006 [INFO] Embedding generator initialized successfully
2025-05-02 23:37:48,085 [INFO] Embedding generator initialized successfully
2025-05-02 23:37:48,137 [INFO] Embedding generator initialized successfully
2025-05-02 23:37:48,141 [INFO] Embedding generator initialized successfully
2025-05-02 23:37:48,191 [INFO] Embedding generator initialized successfully
2025-05-02 23:37:49,174 [ERROR] API request failed: 400 Client Error: Bad Request for url: https://api-f1db6c.stack.tryrelevance.com/latest/studios/d58d3b72-d349-44f4-b5f9-9f03f090fa7a/trigger_webhook?project=8f40138a7b22-4b6d-8b9a-8474a3de12bc
2025-05-02 23:37:49,174 [ERROR] Error processing LinkedIn profile: 1 validation error for LinkedInProfile
full_name
  Field required [type=missing, input_value={'error': 'API request fa...n.com/in/dmn-sangeeth/'}, input_type=dict]
    For further information visit https://errors.pydantic.dev/2.9/v/missing
2025-05-02 23:37:49,174 [ERROR] Error processing resume: Profile processing failed: 1 validation error for LinkedInProfile
full_name
  Field required [type=missing, input_value={'error': 'API request fa...n.com/in/dmn-sangeeth/'}, input_type=dict]
    For further information visit https://errors.pydantic.dev/2.9/v/missing
Traceback (most recent call last):
  File "/home/dmnsangeeth/Desktop/project/ai-recruitment-platform/app/services/linkedin_service.py", line 109, in scraping_linkedin_content
    profile = LinkedInProfile(**profile_data)
  File "/home/dmnsangeeth/anaconda3/envs/gemini/lib/python3.13/site-packages/pydantic/main.py", line 212, in __init__
    validated_self = self.__pydantic_validator__.validate_python(data, self_instance=self)
pydantic_core._pydantic_core.ValidationError: 1 validation error for LinkedInProfile
full_name
  Field required [type=missing, input_value={'error': 'API request fa...n.com/in/dmn-sangeeth/'}, input_type=dict]
    For further information visit https://errors.pydantic.dev/2.9/v/missing

During handling of the above exception, another exception occurred:

Traceback (most recent call last):
  File "/home/dmnsangeeth/Desktop/project/ai-recruitment-platform/app/api/v1/endpoints/linkedin.py", line 52, in upload_linkedin_profile
    profile_data = await linkedin_service.scraping_linkedin_content(
                   ^^^^^^^^^^^^^^^^^^^^^^^^^^^^^^^^^^^^^^^^^^^^^^^^^
        linkedin_url=str(linkedin_url))
        ^^^^^^^^^^^^^^^^^^^^^^^^^^^^^^^
  File "/home/dmnsangeeth/Desktop/project/ai-recruitment-platform/app/services/linkedin_service.py", line 118, in scraping_linkedin_content
    raise ProfileProcessingError(f"Profile processing failed: {str(e)}")
app.utils.exceptions.ProfileProcessingError: Profile processing failed: 1 validation error for LinkedInProfile
full_name
  Field required [type=missing, input_value={'error': 'API request fa...n.com/in/dmn-sangeeth/'}, input_type=dict]
    For further information visit https://errors.pydantic.dev/2.9/v/missing
2025-05-02 23:38:25,028 [INFO] Embedding generator initialized successfully
2025-05-02 23:38:25,079 [INFO] Embedding generator initialized successfully
2025-05-02 23:38:25,114 [INFO] Embedding generator initialized successfully
2025-05-02 23:38:25,118 [INFO] Embedding generator initialized successfully
2025-05-02 23:38:25,150 [INFO] Embedding generator initialized successfully
2025-05-02 23:38:39,067 [ERROR] API request failed: 400 Client Error: Bad Request for url: https://api-f1db6c.stack.tryrelevance.com/latest/studios/d58d3b72-d349-44f4-b5f9-9f03f090fa7a/trigger_webhook?project=8f40138a7b22-4b6d-8b9a-8474a3de12bc
2025-05-02 23:38:39,067 [ERROR] Error processing LinkedIn profile: 1 validation error for LinkedInProfile
full_name
  Field required [type=missing, input_value={'error': 'API request fa...in.com/in/dmn-sangeeth'}, input_type=dict]
    For further information visit https://errors.pydantic.dev/2.9/v/missing
2025-05-02 23:38:39,067 [ERROR] Error processing resume: Profile processing failed: 1 validation error for LinkedInProfile
full_name
  Field required [type=missing, input_value={'error': 'API request fa...in.com/in/dmn-sangeeth'}, input_type=dict]
    For further information visit https://errors.pydantic.dev/2.9/v/missing
Traceback (most recent call last):
  File "/home/dmnsangeeth/Desktop/project/ai-recruitment-platform/app/services/linkedin_service.py", line 109, in scraping_linkedin_content
    profile = LinkedInProfile(**profile_data)
  File "/home/dmnsangeeth/anaconda3/envs/gemini/lib/python3.13/site-packages/pydantic/main.py", line 212, in __init__
    validated_self = self.__pydantic_validator__.validate_python(data, self_instance=self)
pydantic_core._pydantic_core.ValidationError: 1 validation error for LinkedInProfile
full_name
  Field required [type=missing, input_value={'error': 'API request fa...in.com/in/dmn-sangeeth'}, input_type=dict]
    For further information visit https://errors.pydantic.dev/2.9/v/missing

During handling of the above exception, another exception occurred:

Traceback (most recent call last):
  File "/home/dmnsangeeth/Desktop/project/ai-recruitment-platform/app/api/v1/endpoints/linkedin.py", line 52, in upload_linkedin_profile
    profile_data = await linkedin_service.scraping_linkedin_content(
                   ^^^^^^^^^^^^^^^^^^^^^^^^^^^^^^^^^^^^^^^^^^^^^^^^^
        linkedin_url=str(linkedin_url))
        ^^^^^^^^^^^^^^^^^^^^^^^^^^^^^^^
  File "/home/dmnsangeeth/Desktop/project/ai-recruitment-platform/app/services/linkedin_service.py", line 118, in scraping_linkedin_content
    raise ProfileProcessingError(f"Profile processing failed: {str(e)}")
app.utils.exceptions.ProfileProcessingError: Profile processing failed: 1 validation error for LinkedInProfile
full_name
  Field required [type=missing, input_value={'error': 'API request fa...in.com/in/dmn-sangeeth'}, input_type=dict]
    For further information visit https://errors.pydantic.dev/2.9/v/missing
2025-05-02 23:43:54,758 [INFO] Embedding generator initialized successfully
2025-05-02 23:43:54,821 [INFO] Embedding generator initialized successfully
2025-05-02 23:43:54,858 [INFO] Embedding generator initialized successfully
2025-05-02 23:43:54,860 [INFO] Embedding generator initialized successfully
2025-05-02 23:43:54,895 [INFO] Embedding generator initialized successfully
2025-05-02 23:44:27,294 [INFO] Embedding generator initialized successfully
2025-05-02 23:44:27,375 [INFO] Embedding generator initialized successfully
2025-05-02 23:44:27,421 [INFO] Embedding generator initialized successfully
2025-05-02 23:44:27,424 [INFO] Embedding generator initialized successfully
2025-05-02 23:44:27,471 [INFO] Embedding generator initialized successfully
2025-05-02 23:44:58,516 [INFO] Embedding generator initialized successfully
2025-05-02 23:44:58,594 [INFO] Embedding generator initialized successfully
2025-05-02 23:44:58,644 [INFO] Embedding generator initialized successfully
2025-05-02 23:44:58,648 [INFO] Embedding generator initialized successfully
2025-05-02 23:44:58,693 [INFO] Embedding generator initialized successfully
2025-05-02 23:45:52,214 [INFO] Embedding generator initialized successfully
2025-05-02 23:45:52,272 [INFO] Embedding generator initialized successfully
2025-05-02 23:45:52,311 [INFO] Embedding generator initialized successfully
2025-05-02 23:45:52,317 [INFO] Embedding generator initialized successfully
2025-05-02 23:45:52,364 [INFO] Embedding generator initialized successfully
2025-05-02 23:45:54,258 [ERROR] API request failed: 400 Client Error: Bad Request for url: https://api-f1db6c.stack.tryrelevance.com/latest/studios/d58d3b72-d349-44f4-b5f9-9f03f090fa7a/trigger_webhook?project=8f40138a7b22-4b6d-8b9a-8474a3de12bc
2025-05-02 23:45:54,258 [ERROR] Error processing LinkedIn profile: API request failed: 400 Client Error: Bad Request for url: https://api-f1db6c.stack.tryrelevance.com/latest/studios/d58d3b72-d349-44f4-b5f9-9f03f090fa7a/trigger_webhook?project=8f40138a7b22-4b6d-8b9a-8474a3de12bc
2025-05-02 23:47:56,371 [INFO] Embedding generator initialized successfully
2025-05-02 23:47:56,425 [INFO] Embedding generator initialized successfully
2025-05-02 23:47:56,458 [INFO] Embedding generator initialized successfully
2025-05-02 23:47:56,461 [INFO] Embedding generator initialized successfully
2025-05-02 23:47:56,493 [INFO] Embedding generator initialized successfully
2025-05-02 23:49:33,647 [INFO] Embedding generator initialized successfully
2025-05-02 23:49:33,704 [INFO] Embedding generator initialized successfully
2025-05-02 23:49:33,737 [INFO] Embedding generator initialized successfully
2025-05-02 23:49:33,740 [INFO] Embedding generator initialized successfully
2025-05-02 23:49:33,774 [INFO] Embedding generator initialized successfully
2025-05-03 08:32:40,095 [INFO] Embedding generator initialized successfully
2025-05-03 08:32:40,159 [INFO] Embedding generator initialized successfully
2025-05-03 08:32:40,190 [INFO] Embedding generator initialized successfully
2025-05-03 08:32:40,194 [INFO] Embedding generator initialized successfully
2025-05-03 08:32:40,224 [INFO] Embedding generator initialized successfully
2025-05-03 08:34:21,975 [ERROR] API request failed: 400 Client Error: Bad Request for url: https://api-f1db6c.stack.tryrelevance.com/latest/studios/d58d3b72-d349-44f4-b5f9-9f03f090fa7a/trigger_webhook?project=8f40138a7b22-4b6d-8b9a-8474a3de12bc
2025-05-03 08:34:21,977 [ERROR] Error processing LinkedIn profile: 1 validation error for LinkedInProfile
full_name
  Field required [type=missing, input_value={'error': 'API request fa...n.com/in/dmn-sangeeth/'}, input_type=dict]
    For further information visit https://errors.pydantic.dev/2.9/v/missing
2025-05-03 08:34:21,977 [ERROR] Error processing resume: Profile processing failed: 1 validation error for LinkedInProfile
full_name
  Field required [type=missing, input_value={'error': 'API request fa...n.com/in/dmn-sangeeth/'}, input_type=dict]
    For further information visit https://errors.pydantic.dev/2.9/v/missing
Traceback (most recent call last):
  File "/home/dmnsangeeth/Desktop/project/ai-recruitment-platform/app/services/linkedin_service.py", line 109, in scraping_linkedin_content
    profile = LinkedInProfile(**profile_data)
  File "/home/dmnsangeeth/anaconda3/envs/gemini/lib/python3.13/site-packages/pydantic/main.py", line 212, in __init__
    validated_self = self.__pydantic_validator__.validate_python(data, self_instance=self)
pydantic_core._pydantic_core.ValidationError: 1 validation error for LinkedInProfile
full_name
  Field required [type=missing, input_value={'error': 'API request fa...n.com/in/dmn-sangeeth/'}, input_type=dict]
    For further information visit https://errors.pydantic.dev/2.9/v/missing

During handling of the above exception, another exception occurred:

Traceback (most recent call last):
  File "/home/dmnsangeeth/Desktop/project/ai-recruitment-platform/app/api/v1/endpoints/linkedin.py", line 52, in upload_linkedin_profile
    profile_data = await linkedin_service.scraping_linkedin_content(
                   ^^^^^^^^^^^^^^^^^^^^^^^^^^^^^^^^^^^^^^^^^^^^^^^^^
        linkedin_url=str(linkedin_url))
        ^^^^^^^^^^^^^^^^^^^^^^^^^^^^^^^
  File "/home/dmnsangeeth/Desktop/project/ai-recruitment-platform/app/services/linkedin_service.py", line 118, in scraping_linkedin_content
    raise ProfileProcessingError(f"Profile processing failed: {str(e)}")
app.utils.exceptions.ProfileProcessingError: Profile processing failed: 1 validation error for LinkedInProfile
full_name
  Field required [type=missing, input_value={'error': 'API request fa...n.com/in/dmn-sangeeth/'}, input_type=dict]
    For further information visit https://errors.pydantic.dev/2.9/v/missing
2025-05-03 19:41:54,450 [INFO] Embedding generator initialized successfully
2025-05-03 19:41:54,503 [INFO] Embedding generator initialized successfully
2025-05-03 19:41:54,540 [INFO] Embedding generator initialized successfully
2025-05-03 19:41:54,543 [INFO] Embedding generator initialized successfully
2025-05-03 19:41:54,573 [INFO] Embedding generator initialized successfully
2025-05-03 19:42:41,753 [WARNING] Invalid resume detected: Profile contains name, headline, and multiple work experiences.
2025-05-03 19:42:42,676 [INFO] Successfully created embedding for resume: None
2025-05-07 08:13:27,070 [INFO] Embedding generator initialized successfully
2025-05-07 08:13:27,126 [INFO] Embedding generator initialized successfully
2025-05-07 08:13:27,160 [INFO] Embedding generator initialized successfully
2025-05-07 08:13:27,172 [INFO] Embedding generator initialized successfully
2025-05-07 08:13:27,206 [INFO] Embedding generator initialized successfully
2025-05-07 08:48:58,665 [INFO] Embedding generator initialized successfully
2025-05-07 08:48:58,719 [INFO] Embedding generator initialized successfully
2025-05-07 08:48:58,763 [INFO] Embedding generator initialized successfully
2025-05-07 08:48:58,773 [INFO] Embedding generator initialized successfully
2025-05-07 08:48:58,806 [INFO] Embedding generator initialized successfully
2025-05-07 08:53:04,653 [INFO] Embedding generator initialized successfully
2025-05-07 08:53:04,716 [INFO] Embedding generator initialized successfully
2025-05-07 08:53:04,750 [INFO] Embedding generator initialized successfully
2025-05-07 08:53:04,761 [INFO] Embedding generator initialized successfully
2025-05-07 08:53:04,796 [INFO] Embedding generator initialized successfully
2025-05-07 08:54:40,794 [INFO] Embedding generator initialized successfully
2025-05-07 08:54:40,861 [INFO] Embedding generator initialized successfully
2025-05-07 08:54:40,895 [INFO] Embedding generator initialized successfully
2025-05-07 08:54:40,905 [INFO] Embedding generator initialized successfully
2025-05-07 08:54:40,939 [INFO] Embedding generator initialized successfully
2025-05-07 09:07:59,783 [INFO] Embedding generator initialized successfully
2025-05-07 09:07:59,876 [INFO] Embedding generator initialized successfully
2025-05-07 09:07:59,914 [INFO] Embedding generator initialized successfully
2025-05-07 09:07:59,926 [INFO] Embedding generator initialized successfully
2025-05-07 09:07:59,963 [INFO] Embedding generator initialized successfully
2025-05-07 09:12:38,049 [INFO] Embedding generator initialized successfully
2025-05-07 09:12:38,110 [INFO] Embedding generator initialized successfully
2025-05-07 09:12:38,147 [INFO] Embedding generator initialized successfully
2025-05-07 09:12:38,158 [INFO] Embedding generator initialized successfully
2025-05-07 09:12:38,195 [INFO] Embedding generator initialized successfully
2025-05-07 09:51:28,583 [INFO] Embedding generator initialized successfully
2025-05-07 09:51:28,653 [INFO] Embedding generator initialized successfully
2025-05-07 09:51:28,687 [INFO] Embedding generator initialized successfully
2025-05-07 09:51:28,698 [INFO] Embedding generator initialized successfully
2025-05-07 09:51:28,733 [INFO] Embedding generator initialized successfully
2025-05-07 09:57:50,348 [INFO] Embedding generator initialized successfully
2025-05-07 09:57:50,408 [INFO] Embedding generator initialized successfully
2025-05-07 09:57:50,443 [INFO] Embedding generator initialized successfully
2025-05-07 09:57:50,452 [INFO] Embedding generator initialized successfully
2025-05-07 09:57:50,485 [INFO] Embedding generator initialized successfully
2025-05-07 09:58:44,063 [INFO] Embedding generator initialized successfully
2025-05-07 09:58:44,117 [INFO] Embedding generator initialized successfully
2025-05-07 09:58:44,151 [INFO] Embedding generator initialized successfully
2025-05-07 09:58:44,161 [INFO] Embedding generator initialized successfully
2025-05-07 09:58:44,204 [INFO] Embedding generator initialized successfully
2025-05-07 10:01:29,886 [INFO] Embedding generator initialized successfully
2025-05-07 10:01:30,007 [INFO] Embedding generator initialized successfully
2025-05-07 10:01:30,043 [INFO] Embedding generator initialized successfully
2025-05-07 10:01:30,061 [INFO] Embedding generator initialized successfully
2025-05-07 10:01:30,097 [INFO] Embedding generator initialized successfully
2025-05-07 10:14:42,263 [INFO] Embedding generator initialized successfully
2025-05-07 10:14:42,379 [INFO] Embedding generator initialized successfully
2025-05-07 10:14:42,413 [INFO] Embedding generator initialized successfully
2025-05-07 10:14:42,430 [INFO] Embedding generator initialized successfully
2025-05-07 10:14:42,466 [INFO] Embedding generator initialized successfully
2025-05-07 10:14:59,382 [INFO] Embedding generator initialized successfully
2025-05-07 10:14:59,437 [INFO] Embedding generator initialized successfully
2025-05-07 10:14:59,469 [INFO] Embedding generator initialized successfully
2025-05-07 10:14:59,476 [INFO] Embedding generator initialized successfully
2025-05-07 10:14:59,508 [INFO] Embedding generator initialized successfully
2025-05-07 10:25:28,637 [INFO] Embedding generator initialized successfully
2025-05-07 10:25:28,696 [INFO] Embedding generator initialized successfully
2025-05-07 10:25:28,736 [INFO] Embedding generator initialized successfully
2025-05-07 10:25:28,745 [INFO] Embedding generator initialized successfully
2025-05-07 10:25:28,795 [INFO] Embedding generator initialized successfully
2025-05-07 10:31:04,196 [INFO] Embedding generator initialized successfully
2025-05-07 10:31:04,276 [INFO] Embedding generator initialized successfully
2025-05-07 10:31:04,314 [INFO] Embedding generator initialized successfully
2025-05-07 10:31:04,323 [INFO] Embedding generator initialized successfully
2025-05-07 10:31:04,363 [INFO] Embedding generator initialized successfully
2025-05-07 10:31:13,005 [INFO] Embedding generator initialized successfully
2025-05-07 10:31:13,070 [INFO] Embedding generator initialized successfully
2025-05-07 10:31:13,109 [INFO] Embedding generator initialized successfully
2025-05-07 10:31:13,124 [INFO] Embedding generator initialized successfully
2025-05-07 10:31:13,173 [INFO] Embedding generator initialized successfully
2025-05-07 10:31:24,378 [INFO] Embedding generator initialized successfully
2025-05-07 10:31:24,470 [INFO] Embedding generator initialized successfully
2025-05-07 10:31:24,529 [INFO] Embedding generator initialized successfully
2025-05-07 10:31:24,540 [INFO] Embedding generator initialized successfully
2025-05-07 10:31:24,594 [INFO] Embedding generator initialized successfully
2025-05-07 10:31:27,727 [INFO] Embedding generator initialized successfully
2025-05-07 10:31:27,786 [INFO] Embedding generator initialized successfully
2025-05-07 10:31:27,823 [INFO] Embedding generator initialized successfully
2025-05-07 10:31:27,832 [INFO] Embedding generator initialized successfully
2025-05-07 10:31:27,890 [INFO] Embedding generator initialized successfully
2025-05-07 11:47:14,900 [INFO] Embedding generator initialized successfully
2025-05-07 11:47:14,989 [INFO] Embedding generator initialized successfully
2025-05-07 11:47:15,047 [INFO] Embedding generator initialized successfully
2025-05-07 11:47:15,063 [INFO] Embedding generator initialized successfully
2025-05-07 11:47:15,140 [INFO] Embedding generator initialized successfully
2025-05-07 13:13:04,607 [INFO] Embedding generator initialized successfully
2025-05-07 13:13:04,663 [INFO] Embedding generator initialized successfully
2025-05-07 13:13:04,697 [INFO] Embedding generator initialized successfully
2025-05-07 13:13:04,706 [INFO] Embedding generator initialized successfully
2025-05-07 13:13:04,744 [INFO] Embedding generator initialized successfully
2025-05-07 13:27:03,575 [INFO] Embedding generator initialized successfully
2025-05-07 13:27:03,659 [INFO] Embedding generator initialized successfully
2025-05-07 13:27:03,707 [INFO] Embedding generator initialized successfully
2025-05-07 13:27:03,722 [INFO] Embedding generator initialized successfully
2025-05-07 13:27:03,764 [INFO] Embedding generator initialized successfully
2025-05-07 13:37:13,005 [INFO] Embedding generator initialized successfully
2025-05-07 13:37:13,089 [INFO] Embedding generator initialized successfully
2025-05-07 13:37:13,140 [INFO] Embedding generator initialized successfully
2025-05-07 13:37:13,149 [INFO] Embedding generator initialized successfully
2025-05-07 13:37:13,196 [INFO] Embedding generator initialized successfully
2025-05-07 13:37:40,562 [INFO] Embedding generator initialized successfully
2025-05-07 13:37:40,624 [INFO] Embedding generator initialized successfully
2025-05-07 13:37:40,660 [INFO] Embedding generator initialized successfully
2025-05-07 13:37:40,668 [INFO] Embedding generator initialized successfully
2025-05-07 13:37:40,702 [INFO] Embedding generator initialized successfully
2025-05-07 13:43:08,260 [INFO] Embedding generator initialized successfully
2025-05-07 13:43:08,319 [INFO] Embedding generator initialized successfully
2025-05-07 13:43:08,358 [INFO] Embedding generator initialized successfully
2025-05-07 13:43:08,369 [INFO] Embedding generator initialized successfully
2025-05-07 13:43:08,408 [INFO] Embedding generator initialized successfully
2025-05-07 14:39:31,287 [INFO] Embedding generator initialized successfully
2025-05-07 14:39:31,355 [INFO] Embedding generator initialized successfully
2025-05-07 14:39:31,390 [INFO] Embedding generator initialized successfully
2025-05-07 14:39:31,400 [INFO] Embedding generator initialized successfully
2025-05-07 14:39:31,444 [INFO] Embedding generator initialized successfully
2025-05-07 14:39:42,096 [INFO] Embedding generator initialized successfully
2025-05-07 14:39:42,188 [INFO] Embedding generator initialized successfully
2025-05-07 14:39:42,240 [INFO] Embedding generator initialized successfully
2025-05-07 14:39:42,254 [INFO] Embedding generator initialized successfully
2025-05-07 14:39:42,315 [INFO] Embedding generator initialized successfully
2025-05-07 14:40:04,129 [ERROR] Unexpected error processing LinkedIn profile: 'function' object has no attribute 'linkedin_url'
Traceback (most recent call last):
  File "/home/dmnsangeeth/Desktop/project/ai-recruitment-platform/app/api/v1/endpoints/linkedin.py", line 40, in upload_linkedin_profile
    logger.info(f"Processing LinkedIn profile: {requests.request.linkedin_url}")
                                                ^^^^^^^^^^^^^^^^^^^^^^^^^^^^^
AttributeError: 'function' object has no attribute 'linkedin_url'
2025-05-07 14:41:53,218 [INFO] Embedding generator initialized successfully
2025-05-07 14:41:53,292 [INFO] Embedding generator initialized successfully
2025-05-07 14:41:53,330 [INFO] Embedding generator initialized successfully
2025-05-07 14:41:53,339 [INFO] Embedding generator initialized successfully
2025-05-07 14:41:53,376 [INFO] Embedding generator initialized successfully
2025-05-07 14:44:37,949 [INFO] Embedding generator initialized successfully
2025-05-07 14:44:38,077 [INFO] Embedding generator initialized successfully
2025-05-07 14:44:38,116 [INFO] Embedding generator initialized successfully
2025-05-07 14:44:38,138 [INFO] Embedding generator initialized successfully
2025-05-07 14:44:38,176 [INFO] Embedding generator initialized successfully
2025-05-07 14:48:41,100 [INFO] Embedding generator initialized successfully
2025-05-07 14:48:41,243 [INFO] Embedding generator initialized successfully
2025-05-07 14:48:41,278 [INFO] Embedding generator initialized successfully
2025-05-07 14:48:41,296 [INFO] Embedding generator initialized successfully
2025-05-07 14:48:41,330 [INFO] Embedding generator initialized successfully
2025-05-07 14:49:30,710 [ERROR] Unexpected error in LinkedIn service: Timeout value connect was 30, but it must be an int, float or None.
Traceback (most recent call last):
  File "/home/dmnsangeeth/Desktop/project/ai-recruitment-platform/app/services/linkedin_service.py", line 39, in scraping_linkedin_content
    response = self._make_api_request(headers,payload)
  File "/home/dmnsangeeth/Desktop/project/ai-recruitment-platform/app/services/linkedin_service.py", line 115, in _make_api_request
    response = requests.post(
        f"{self.endpoint}?project={self.project_id}",
    ...<2 lines>...
        timeout=self.api_timeout
    )
  File "/home/dmnsangeeth/anaconda3/envs/gemini/lib/python3.13/site-packages/requests/api.py", line 115, in post
    return request("post", url, data=data, json=json, **kwargs)
  File "/home/dmnsangeeth/anaconda3/envs/gemini/lib/python3.13/site-packages/requests/api.py", line 59, in request
    return session.request(method=method, url=url, **kwargs)
           ~~~~~~~~~~~~~~~^^^^^^^^^^^^^^^^^^^^^^^^^^^^^^^^^^
  File "/home/dmnsangeeth/anaconda3/envs/gemini/lib/python3.13/site-packages/requests/sessions.py", line 589, in request
    resp = self.send(prep, **send_kwargs)
  File "/home/dmnsangeeth/anaconda3/envs/gemini/lib/python3.13/site-packages/requests/sessions.py", line 703, in send
    r = adapter.send(request, **kwargs)
  File "/home/dmnsangeeth/anaconda3/envs/gemini/lib/python3.13/site-packages/requests/adapters.py", line 664, in send
    timeout = TimeoutSauce(connect=timeout, read=timeout)
  File "/home/dmnsangeeth/anaconda3/envs/gemini/lib/python3.13/site-packages/urllib3/util/timeout.py", line 115, in __init__
    self._connect = self._validate_timeout(connect, "connect")
                    ~~~~~~~~~~~~~~~~~~~~~~^^^^^^^^^^^^^^^^^^^^
  File "/home/dmnsangeeth/anaconda3/envs/gemini/lib/python3.13/site-packages/urllib3/util/timeout.py", line 165, in _validate_timeout
    raise ValueError(
    ...<2 lines>...
    ) from None
ValueError: Timeout value connect was 30, but it must be an int, float or None.
2025-05-07 14:49:30,718 [ERROR] HTTP error while processing LinkedIn profile: 500: Internal server error: Timeout value connect was 30, but it must be an int, float or None.
2025-05-07 15:06:08,902 [INFO] Embedding generator initialized successfully
2025-05-07 15:06:09,033 [INFO] Embedding generator initialized successfully
2025-05-07 15:06:09,072 [INFO] Embedding generator initialized successfully
2025-05-07 15:06:09,092 [INFO] Embedding generator initialized successfully
2025-05-07 15:06:09,129 [INFO] Embedding generator initialized successfully
2025-05-07 15:08:50,000 [INFO] Embedding generator initialized successfully
2025-05-07 15:08:50,054 [INFO] Embedding generator initialized successfully
2025-05-07 15:08:50,087 [INFO] Embedding generator initialized successfully
2025-05-07 15:08:50,098 [INFO] Embedding generator initialized successfully
2025-05-07 15:08:50,132 [INFO] Embedding generator initialized successfully
2025-05-07 15:08:55,372 [INFO] Embedding generator initialized successfully
2025-05-07 15:08:55,441 [INFO] Embedding generator initialized successfully
2025-05-07 15:08:55,483 [INFO] Embedding generator initialized successfully
2025-05-07 15:08:55,490 [INFO] Embedding generator initialized successfully
2025-05-07 15:08:55,538 [INFO] Embedding generator initialized successfully
2025-05-07 15:20:48,998 [INFO] Embedding generator initialized successfully
2025-05-07 15:20:49,065 [INFO] Embedding generator initialized successfully
2025-05-07 15:20:49,104 [INFO] Embedding generator initialized successfully
2025-05-07 15:20:49,116 [INFO] Embedding generator initialized successfully
2025-05-07 15:20:49,163 [INFO] Embedding generator initialized successfully
2025-05-07 18:13:41,684 [INFO] Embedding generator initialized successfully
2025-05-07 18:13:41,777 [INFO] Embedding generator initialized successfully
2025-05-07 18:13:41,822 [INFO] Embedding generator initialized successfully
2025-05-07 18:13:41,832 [INFO] Embedding generator initialized successfully
2025-05-07 18:13:41,884 [INFO] Embedding generator initialized successfully
2025-05-07 18:14:11,142 [INFO] Embedding generator initialized successfully
2025-05-07 18:14:11,262 [INFO] Embedding generator initialized successfully
2025-05-07 18:14:11,331 [INFO] Embedding generator initialized successfully
2025-05-07 18:14:11,346 [INFO] Embedding generator initialized successfully
2025-05-07 18:14:11,412 [INFO] Embedding generator initialized successfully
2025-05-07 23:29:17,262 [INFO] Embedding generator initialized successfully
2025-05-07 23:29:17,339 [INFO] Embedding generator initialized successfully
2025-05-07 23:29:17,385 [INFO] Embedding generator initialized successfully
2025-05-07 23:29:17,405 [INFO] Embedding generator initialized successfully
2025-05-07 23:29:17,480 [INFO] Embedding generator initialized successfully
2025-05-08 09:11:06,674 [INFO] Embedding generator initialized successfully
2025-05-08 09:11:06,739 [INFO] Embedding generator initialized successfully
2025-05-08 09:11:06,775 [INFO] Embedding generator initialized successfully
2025-05-08 09:11:06,786 [INFO] Embedding generator initialized successfully
2025-05-08 09:11:06,821 [INFO] Embedding generator initialized successfully
2025-05-08 09:11:06,826 [INFO] Embedding generator initialized successfully
2025-05-08 09:11:06,860 [INFO] Embedding generator initialized successfully
2025-05-08 09:11:51,695 [INFO] File saved at: storage/resumes/resume_20250508_091151.pdf
2025-05-08 09:11:52,782 [INFO] HTTP Request: POST https://generativelanguage.googleapis.com/upload/v1beta/files "HTTP/1.1 200 OK"
2025-05-08 09:11:56,163 [INFO] HTTP Request: POST https://generativelanguage.googleapis.com/upload/v1beta/files?upload_id=AAO2Vwq9gDAgVWEHKInrx7CNmZ-iI0JJknS25LHxGD9nweIx4UoMpBn3HsZtjxNg4dQyVI3VZh4nPJfqJufbY2-pTcUZlylVFKSRBZyAwu3lyw&upload_protocol=resumable "HTTP/1.1 200 OK"
2025-05-08 09:11:56,197 [INFO] AFC is enabled with max remote calls: 10.
2025-05-08 09:12:06,731 [INFO] HTTP Request: POST https://generativelanguage.googleapis.com/v1beta/models/gemini-2.0-flash:generateContent "HTTP/1.1 200 OK"
2025-05-08 09:12:06,734 [INFO] AFC remote call 1 is done.
2025-05-08 09:12:24,734 [INFO] Successfully created embedding for resume: NISHAN SANGEETH
2025-05-08 09:12:25,821 [INFO] Successfully processed and stored resume for NISHAN SANGEETH
2025-05-08 09:12:26,281 [INFO] Successfully created embedding for resume: None
